Workbook

Sheet Home
B3: XXIII Mundial USA/MEX/CAN 2026
C5: 📋 Selecciona idioma
C6: Español | K6: Introducir resultados
C7: 🕒 Selecciona horario
C8: UTC -4 | K8: Fixture
C9: ✍️ Escribe tu nombre
C10: Gaby | K10: Help
E16: Si quieres organizar una porra (quiniela) con tu grupo puedes descargar el archivo de adminsitrador desde el enlace de abajo
E17: ▼ Descargar Excel Administrador Porra ▼ | K17: Video►Tutorial
E21: Share:
E22: Whatsapp | F22: Telegram | G22: Mail | H22: X | I22: in
K23: © Miguel Angel Tejero. 2026 | L23: Donar

Sheet WORLDCUP
W1: XXIII Mundial USA/MEX/CAN 2026 | DN1: Horarios!$P$3
D3: WINNER | E3: Empate1L | F3: Empate1V | H3: Empate2L | I3: Empate2V | K3: Empate3L | L3: Empate3V | N3: Empate4L | O3: Empate4V | Q3: Empate5L | R3: Empate5V | T3: Empate6L | U3: Empate6V | X3: Fecha | Y3: Hora | Z3: Jor. | AA3: Casa | AC3: Gol | AD3: Gol | AF3: Fuera | AJ3: Grupo | AV3: ¡EMPATE! Puedes seleccionar el orden de los empatados. | AZ3: No
A4: NombreEquipo | B4: A | C4: 4 | D4: {=IF(OR(AC4="",AD4=""),"Pendiente",IF(AC4>AD4,"Local",IF(AC4<AD4,"Visitante","Empate")))} -> Local | E4: {=IF(D4="Pendiente","-",INDEX($BT$6:$BT$53,MATCH($AA4,$BD$6:$BD$53,0)))} -> P.1 (4) | F4: {=IF(D4="Pendiente","-",INDEX($BT$6:$BT$53,MATCH($AF4,$BD$6:$BD$53,0)))} -> P.1 (4) | H4: {=IF(D4="Pendiente","-",INDEX($BZ$6:$BZ$53,MATCH($AA4,$BD$6:$BD$53,0)))} -> P.1 (4) | I4: {=IF(D4="Pendiente","-",INDEX($BZ$6:$BZ$53,MATCH($AF4,$BD$6:$BD$53,0)))} -> P.1 (4) | K4: {=IF(D4="Pendiente","-",INDEX($CE$6:$CE$53,MATCH($AA4,$BD$6:$BD$53,0)))} -> P.1 (4) | L4: {=IF(D4="Pendiente","-",INDEX($CE$6:$CE$53,MATCH($AF4,$BD$6:$BD$53,0)))} -> P.1 (4) | N4: {=IF(D4="Pendiente","-",INDEX($CH$6:$CH$53,MATCH($AA4,$BD$6:$BD$53,0)))} -> P.1 (4) | O4: {=IF(D4="Pendiente","-",INDEX($CH$6:$CH$53,MATCH($AF4,$BD$6:$BD$53,0)))} -> P.1 (4) | Q4: {=IF(D4="Pendiente","-",INDEX($CN$6:$CN$53,MATCH($AA4,$BD$6:$BD$53,0)))} -> P.1 (4) | R4: {=IF(D4="Pendiente","-",INDEX($CN$6:$CN$53,MATCH($AF4,$BD$6:$BD$53,0)))} -> P.1 (4) | T4: {=IF(D4="Pendiente","-",INDEX($CS$6:$CS$53,MATCH($AA4,$BD$6:$BD$53,0)))} -> P.1 (4) | U4: {=IF(D4="Pendiente","-",INDEX($CS$6:$CS$53,MATCH($AF4,$BD$6:$BD$53,0)))} -> P.1 (4) | W4: A | X4: 46184.625 | Y4: 46184.625 | Z4: J1 | AA4: {=A5} -> México | AC4: 2 | AD4: 1 | AF4: {=A6} -> Sudáfrica | AG4: {=IF(NOT(OR(ISBLANK(AC4),ISBLANK(AD4))),1,0)} -> 1 | AH4: 1 | AJ4: {=CONCATENATE(AJ3," ",B4)} -> Grupo A | AV4: {=IF(AU5>0,$AV$3,"")} -> ¡EMPATE! Puedes seleccionar el orden de los empatados. | DC4: Grupos: bombo; terceros: orden alfa
A5: México | D5: {=IF(OR(AC5="",AD5=""),"Pendiente",IF(AC5>AD5,"Local",IF(AC5<AD5,"Visitante","Empate")))} -> Local | E5: {=IF(D5="Pendiente","-",INDEX($BT$6:$BT$53,MATCH($AA5,$BD$6:$BD$53,0)))} -> P.1 (4) | F5: {=IF(D5="Pendiente","-",INDEX($BT$6:$BT$53,MATCH($AF5,$BD$6:$BD$53,0)))} -> P.1 (4) | H5: {=IF(D5="Pendiente","-",INDEX($BZ$6:$BZ$53,MATCH($AA5,$BD$6:$BD$53,0)))} -> P.1 (4) | I5: {=IF(D5="Pendiente","-",INDEX($BZ$6:$BZ$53,MATCH($AF5,$BD$6:$BD$53,0)))} -> P.1 (4) | K5: {=IF(D5="Pendiente","-",INDEX($CE$6:$CE$53,MATCH($AA5,$BD$6:$BD$53,0)))} -> P.1 (4) | L5: {=IF(D5="Pendiente","-",INDEX($CE$6:$CE$53,MATCH($AF5,$BD$6:$BD$53,0)))} -> P.1 (4) | N5: {=IF(D5="Pendiente","-",INDEX($CH$6:$CH$53,MATCH($AA5,$BD$6:$BD$53,0)))} -> P.1 (4) | O5: {=IF(D5="Pendiente","-",INDEX($CH$6:$CH$53,MATCH($AF5,$BD$6:$BD$53,0)))} -> P.1 (4) | Q5: {=IF(D5="Pendiente","-",INDEX($CN$6:$CN$53,MATCH($AA5,$BD$6:$BD$53,0)))} -> P.1 (4) | R5: {=IF(D5="Pendiente","-",INDEX($CN$6:$CN$53,MATCH($AF5,$BD$6:$BD$53,0)))} -> P.1 (4) | T5: {=IF(D5="Pendiente","-",INDEX($CS$6:$CS$53,MATCH($AA5,$BD$6:$BD$53,0)))} -> P.1 (4) | U5: {=IF(D5="Pendiente","-",INDEX($CS$6:$CS$53,MATCH($AF5,$BD$6:$BD$53,0)))} -> P.1 (4) | X5: 46184.917 | Y5: 46184.917 | Z5: {=$Z$4} -> J1 | AA5: {=A7} -> Corea del Sur | AC5: 2 | AD5: 1 | AF5: {=A8} -> República Checa | AG5: {=IF(NOT(OR(ISBLANK(AC5),ISBLANK(AD5))),1,0)} -> 1 | AH5: 2 | AJ5: Pos | AL5: Selección | AM5: Pts | AN5: J | AO5: G | AP5: E | AQ5: P | AR5: GF | AS5: GC | AT5: DG | AU5: {=COUNTIF(AU6:AU9,">1")} -> 4 | AY5: {=AL5} -> Selección | AZ5: Puntos penalizados | BC5: Grupo | BD5: Selección | BE5: {=AM5} -> Pts | BF5: {=AN5} -> J | BG5: {=AO5} -> G | BH5: {=AP5} -> E | BI5: {=AQ5} -> P | BJ5: {=AR5} -> GF | BK5: {=AS5} -> GC | BL5: {=AT5} -> DG | BM5: PosF1 | BN5: PosF3 | BO5: Participa | BP5: Pos0 | BQ5: Empate0 | BR5: PTS | BS5: Posicion1 | BT5: Empate1 | BU5: PGPart1 | BV5: PEPart1 | BW5: PPPart1 | BX5: PTSPart1 | BY5: Posicion2 | BZ5: Empate2 | CA5: GFPart1 | CB5: GCPart1 | CC5: DGPArt1 | CD5: Posicion3 | CE5: Empate3 | CF5: GFPart1 | CG5: Posicion4 | CH5: Empate4 | CI5: PGPart2 | CJ5: PEPart2 | CK5: PPPart2 | CL5: PTSPart2 | CM5: Posicion5 | CN5: Empate5 | CO5: GFPart2 | CP5: GCPart2 | CQ5: DGPArt2 | CR5: Posicion6 | CS5: Empate6 | CT5: GFPart2 | CU5: Posicion7 | CV5: Empate7 | CW5: DG | CX5: Posicion8 | CY5: Empate8 | CZ5: GF | DA5: Posicion9 | DB5: Empate9 | DC5: OrdenAlfa/Bombo | DD5: PosicionF1 | DF5: PosicionF2 | DG5: Criterio/Fila | DH5: PosicionF3 | DJ5: POS | DK5: Numero Partidos disputados grupo | DL5: CANT | DM5: CONCAT | DN5: DESEMPATE EN SELECTOR | DP5: POSGRUPO | DQ5: PAIS
A6: Sudáfrica | D6: {=IF(OR(AC6="",AD6=""),"Pendiente",IF(AC6>AD6,"Local",IF(AC6<AD6,"Visitante","Empate")))} -> Local | E6: {=IF(D6="Pendiente","-",INDEX($BT$6:$BT$53,MATCH($AA6,$BD$6:$BD$53,0)))} -> P.1 (4) | F6: {=IF(D6="Pendiente","-",INDEX($BT$6:$BT$53,MATCH($AF6,$BD$6:$BD$53,0)))} -> P.1 (4) | H6: {=IF(D6="Pendiente","-",INDEX($BZ$6:$BZ$53,MATCH($AA6,$BD$6:$BD$53,0)))} -> P.1 (4) | I6: {=IF(D6="Pendiente","-",INDEX($BZ$6:$BZ$53,MATCH($AF6,$BD$6:$BD$53,0)))} -> P.1 (4) | K6: {=IF(D6="Pendiente","-",INDEX($CE$6:$CE$53,MATCH($AA6,$BD$6:$BD$53,0)))} -> P.1 (4) | L6: {=IF(D6="Pendiente","-",INDEX($CE$6:$CE$53,MATCH($AF6,$BD$6:$BD$53,0)))} -> P.1 (4) | N6: {=IF(D6="Pendiente","-",INDEX($CH$6:$CH$53,MATCH($AA6,$BD$6:$BD$53,0)))} -> P.1 (4) | O6: {=IF(D6="Pendiente","-",INDEX($CH$6:$CH$53,MATCH($AF6,$BD$6:$BD$53,0)))} -> P.1 (4) | Q6: {=IF(D6="Pendiente","-",INDEX($CN$6:$CN$53,MATCH($AA6,$BD$6:$BD$53,0)))} -> P.1 (4) | R6: {=IF(D6="Pendiente","-",INDEX($CN$6:$CN$53,MATCH($AF6,$BD$6:$BD$53,0)))} -> P.1 (4) | T6: {=IF(D6="Pendiente","-",INDEX($CS$6:$CS$53,MATCH($AA6,$BD$6:$BD$53,0)))} -> P.1 (4) | U6: {=IF(D6="Pendiente","-",INDEX($CS$6:$CS$53,MATCH($AF6,$BD$6:$BD$53,0)))} -> P.1 (4) | X6: 46191.5 | Y6: 46191.5 | Z6: J2 | AA6: {=A8} -> República Checa | AC6: 2 | AD6: 1 | AF6: {=A6} -> Sudáfrica | AG6: {=IF(NOT(OR(ISBLANK(AC6),ISBLANK(AD6))),1,0)} -> 1 | AH6: 25 | AI6: {=AJ6&$B$4} -> 1A | AJ6: 1 | AL6: {=IFERROR(INDEX($BD$6:$BD$53,MATCH(AI6,$BN$6:$BN$53,0)),"")} -> México | AM6: {=INDEX($BE$6:$BN$53,MATCH($AL6,$BD$6:$BD$53,0),MATCH(AM$5,$BE$5:$BN$5,0))} -> 9 | AN6: {=INDEX($BE$6:$BN$53,MATCH($AL6,$BD$6:$BD$53,0),MATCH(AN$5,$BE$5:$BN$5,0))} -> 3 | AO6: {=INDEX($BE$6:$BN$53,MATCH($AL6,$BD$6:$BD$53,0),MATCH(AO$5,$BE$5:$BN$5,0))} -> 3 | AP6: {=INDEX($BE$6:$BN$53,MATCH($AL6,$BD$6:$BD$53,0),MATCH(AP$5,$BE$5:$BN$5,0))} -> 0 | AQ6: {=INDEX($BE$6:$BN$53,MATCH($AL6,$BD$6:$BD$53,0),MATCH(AQ$5,$BE$5:$BN$5,0))} -> 0 | AR6: {=INDEX($BE$6:$BN$53,MATCH($AL6,$BD$6:$BD$53,0),MATCH(AR$5,$BE$5:$BN$5,0))} -> 7 | AS6: {=INDEX($BE$6:$BN$53,MATCH($AL6,$BD$6:$BD$53,0),MATCH(AS$5,$BE$5:$BN$5,0))} -> 2 | AT6: {=INDEX($BE$6:$BN$53,MATCH($AL6,$BD$6:$BD$53,0),MATCH(AT$5,$BE$5:$BN$5,0))} -> 5 | AU6: {=INDEX($DL$6:$DL$53,MATCH(AI6,$DP$6:$DP$53,0))} -> 4 | AV6: {=INDEX($BD$6:$BD$53,MATCH(AI6,$BM$6:$BM$53,0))} -> México | AY6: {=A5} -> México | BC6: A | BD6: México | BE6: {=BG6*3+BH6+IF($AZ$3="No",0,INDEX($AZ$6:$AZ$97,MATCH(BD6,$AY$6:$AY$97,0)))} -> 9 | BF6: {=BG6+BH6+BI6} -> 3 | BG6: {=COUNTIFS($AA$4:$AA$97,BD6,$D$4:$D$97,"Local")+COUNTIFS($AF$4:$AF$97,BD6,$D$4:$D$97,"Visitante")} -> 3 | BH6: {=COUNTIFS($AA$4:$AA$97,BD6,$D$4:$D$97,"Empate")+COUNTIFS($AF$4:$AF$97,BD6,$D$4:$D$97,"Empate")} -> 0 | BI6: {=COUNTIFS($AF$4:$AF$97,BD6,$D$4:$D$97,"Local")+COUNTIFS($AA$4:$AA$97,BD6,$D$4:$D$97,"Visitante")} -> 0 | BJ6: {=SUMIFS($AC$4:$AC$97,$AA$4:$AA$97,BD6,$D$4:$D$97,"<>"&"Pendiente",$AC$4:$AC$97,"<>"&"",$AD$4:$AD$97,"<>"&"")+SUMIFS($AD$4:$AD$97,$AF$4:$AF$97,BD6,$D$4:$D$97,"<>"&"Pendiente",$AC$4:$AC$97,"<>"&"",$AD$4:$AD$97,"<>"&"")} -> 7 | BK6: {=SUMIFS($AC$4:$AC$97,$AF$4:$AF$97,BD6,$D$4:$D$97,"<>"&"Pendiente",$AC$4:$AC$97,"<>"&"",$AD$4:$AD$97,"<>"&"")+SUMIFS($AD$4:$AD$97,$AA$4:$AA$97,BD6,$D$4:$D$97,"<>"&"Pendiente",$AC$4:$AC$97,"<>"&"",$AD$4:$AD$97,"<>"&"")} -> 2 | BL6: {=BJ6-BK6} -> 5 | BM6: {=DD6&BC6} -> 1A | BN6: {=DH6&BC6} -> 1A | BO6: {=IF(AND($AJ$99=144,BF6>=1),1,0)} -> 0 | BP6: 1 | BQ6: P.1 (4) | BR6: {=IF($BQ6="-","-",BE6)} -> 9 | BS6: 1 | BT6: P.1 (4) | BU6: {=IF($BT6="-","-",COUNTIFS($AA$4:$AA$97,$BD6,$D$4:$D$97,"Local",$F$4:$F$97,$BT6)+COUNTIFS($AF$4:$AF$97,$BD6,$D$4:$D$97,"Visitante",$E$4:$E$97,$BT6))} -> 3 | BV6: {=IF($BT6="-","-",COUNTIFS($AA$4:$AA$97,$BD6,$D$4:$D$97,"Empate",$F$4:$F$97,$BT6)+COUNTIFS($AF$4:$AF$97,$BD6,$D$4:$D$97,"Empate",$E$4:$E$97,$BT6))} -> 0 | BW6: {=IF($BT6="-","-",COUNTIFS($AA$4:$AA$97,$BD6,$D$4:$D$97,"Visitante",$F$4:$F$97,$BT6)+COUNTIFS($AF$4:$AF$97,$BD6,$D$4:$D$97,"Local",$E$4:$E$97,$BT6))} -> 0 | BX6: {=IF($BT6="-","-",BU6*3+BV6)} -> 9 | BY6: 1 | BZ6: P.1 (4) | CA6: {=IF($BZ6="-","-",SUMIFS($AC$4:$AC$97,$AA$4:$AA$97,$BD6,$I$4:$I$97,$BZ6)+SUMIFS($AD$4:$AD$97,$AF$4:$AF$97,$BD6,$H$4:$H$97,$BZ6))} -> 7 | CB6: {=IF($BZ6="-","-",SUMIFS($AD$4:$AD$97,$AA$4:$AA$97,$BD6,$I$4:$I$97,$BZ6)+SUMIFS($AC$4:$AC$97,$AF$4:$AF$97,$BD6,$H$4:$H$97,$BZ6))} -> 2 | CC6: {=IF($BZ6="-","-",CA6-CB6)} -> 5 | CD6: 1 | CE6: P.1 (4) | CF6: {=IF($CE6="-","-",SUMIFS($AC$4:$AC$97,$AA$4:$AA$97,$BD6,$L$4:$L$97,$CE6)+SUMIFS($AD$4:$AD$97,$AF$4:$AF$97,$BD6,$K$4:$K$97,$CE6))} -> 7 | CG6: 1 | CH6: P.1 (4) | CI6: {=IF($CH6="-","-",COUNTIFS($AA$4:$AA$97,$BD6,$D$4:$D$97,"Local",$O$4:$O$97,$CH6)+COUNTIFS($AF$4:$AF$97,$BD6,$D$4:$D$97,"Visitante",$N$4:$N$97,$CH6))} -> 3 | CJ6: {=IF($CH6="-","-",COUNTIFS($AA$4:$AA$97,$BD6,$D$4:$D$97,"Empate",$O$4:$O$97,$CH6)+COUNTIFS($AF$4:$AF$97,$BD6,$D$4:$D$97,"Empate",$N$4:$N$97,$CH6))} -> 0 | CK6: {=IF($CH6="-","-",COUNTIFS($AA$4:$AA$97,$BD6,$D$4:$D$97,"Visitante",$O$4:$O$97,$CH6)+COUNTIFS($AF$4:$AF$97,$BD6,$D$4:$D$97,"Local",$N$4:$N$97,$CH6))} -> 0 | CL6: {=IF($CH6="-","-",CI6*3+CJ6)} -> 9 | CM6: 1 | CN6: P.1 (4) | CO6: {=IF($CN6="-","-",SUMIFS($AC$4:$AC$97,$AA$4:$AA$97,$BD6,$R$4:$R$97,$CN6)+SUMIFS($AD$4:$AD$97,$AF$4:$AF$97,$BD6,$Q$4:$Q$97,$CN6))} -> 7 | CP6: {=IF($CN6="-","-",SUMIFS($AD$4:$AD$97,$AA$4:$AA$97,$BD6,$R$4:$R$97,$CN6)+SUMIFS($AC$4:$AC$97,$AF$4:$AF$97,$BD6,$Q$4:$Q$97,$CN6))} -> 2 | CQ6: {=IF($CN6="-","-",CO6-CP6)} -> 5 | CR6: 1 | CS6: P.1 (4) | CT6: {=IF($CS6="-","-",SUMIFS($AC$4:$AC$97,$AA$4:$AA$97,$BD6,$U$4:$U$97,$CS6)+SUMIFS($AD$4:$AD$97,$AF$4:$AF$97,$BD6,$T$4:$T$97,$CS6))} -> 7 | CU6: 1 | CV6: P.1 (4) | CW6: {=IF(CV6="-","-",BL6)} -> 5 | CX6: 1 | CY6: P.1 (4) | CZ6: {=IF(CY6="-","-",BJ6)} -> 7 | DA6: 1 | DB6: P.1 (4) | DC6: 1 | DD6: 1 | DF6: {=IF(OR(INDEX($AW$6:$AW$97,MATCH($BD6,$AV$6:$AV$97,0))="",DB6="-"),DD6,INDEX($AW$6:$AW$97,MATCH($BD6,$AV$6:$AV$97,0))+DD6/1000)} -> 1 | DG6: 0 | DH6: 1 | DJ6: {=INDEX($DA$6:$DA$53,MATCH($DQ6,$BD$6:$BD$53,0))} -> 1 | DK6: {=SUMIF($BC$6:$BC$53,BC6,$BF$6:$BF$53)} -> 12 | DL6: {=IF(OR(DK6=12,$AJ$99=144),COUNTIFS($DJ$6:$DJ$53,DJ6,$BC$6:$BC$53,BC6),1)} -> 4 | DM6: {=DJ6&"."&DL6} -> 1.4 | DN6: 1 | DP6: 1A | DQ6: {=INDEX($BD$6:$BD$53,MATCH(DP6,$BM$6:$BM$53,0))} -> México
A7: Corea del Sur | D7: {=IF(OR(AC7="",AD7=""),"Pendiente",IF(AC7>AD7,"Local",IF(AC7<AD7,"Visitante","Empate")))} -> Local | E7: {=IF(D7="Pendiente","-",INDEX($BT$6:$BT$53,MATCH($AA7,$BD$6:$BD$53,0)))} -> P.1 (4) | F7: {=IF(D7="Pendiente","-",INDEX($BT$6:$BT$53,MATCH($AF7,$BD$6:$BD$53,0)))} -> P.1 (4) | H7: {=IF(D7="Pendiente","-",INDEX($BZ$6:$BZ$53,MATCH($AA7,$BD$6:$BD$53,0)))} -> P.1 (4) | I7: {=IF(D7="Pendiente","-",INDEX($BZ$6:$BZ$53,MATCH($AF7,$BD$6:$BD$53,0)))} -> P.1 (4) | K7: {=IF(D7="Pendiente","-",INDEX($CE$6:$CE$53,MATCH($AA7,$BD$6:$BD$53,0)))} -> P.1 (4) | L7: {=IF(D7="Pendiente","-",INDEX($CE$6:$CE$53,MATCH($AF7,$BD$6:$BD$53,0)))} -> P.1 (4) | N7: {=IF(D7="Pendiente","-",INDEX($CH$6:$CH$53,MATCH($AA7,$BD$6:$BD$53,0)))} -> P.1 (4) | O7: {=IF(D7="Pendiente","-",INDEX($CH$6:$CH$53,MATCH($AF7,$BD$6:$BD$53,0)))} -> P.1 (4) | Q7: {=IF(D7="Pendiente","-",INDEX($CN$6:$CN$53,MATCH($AA7,$BD$6:$BD$53,0)))} -> P.1 (4) | R7: {=IF(D7="Pendiente","-",INDEX($CN$6:$CN$53,MATCH($AF7,$BD$6:$BD$53,0)))} -> P.1 (4) | T7: {=IF(D7="Pendiente","-",INDEX($CS$6:$CS$53,MATCH($AA7,$BD$6:$BD$53,0)))} -> P.1 (4) | U7: {=IF(D7="Pendiente","-",INDEX($CS$6:$CS$53,MATCH($AF7,$BD$6:$BD$53,0)))} -> P.1 (4) | X7: 46191.875 | Y7: 46191.875 | Z7: {=$Z$6} -> J2 | AA7: {=A5} -> México | AC7: 2 | AD7: 1 | AF7: {=A7} -> Corea del Sur | AG7: {=IF(NOT(OR(ISBLANK(AC7),ISBLANK(AD7))),1,0)} -> 1 | AH7: 28 | AI7: {=AJ7&$B$4} -> 2A | AJ7: 2 | AL7: {=IFERROR(INDEX($BD$6:$BD$53,MATCH(AI7,$BN$6:$BN$53,0)),"")} -> Sudáfrica | AM7: {=INDEX($BE$6:$BN$53,MATCH($AL7,$BD$6:$BD$53,0),MATCH(AM$5,$BE$5:$BN$5,0))} -> 0 | AN7: {=INDEX($BE$6:$BN$53,MATCH($AL7,$BD$6:$BD$53,0),MATCH(AN$5,$BE$5:$BN$5,0))} -> 3 | AO7: {=INDEX($BE$6:$BN$53,MATCH($AL7,$BD$6:$BD$53,0),MATCH(AO$5,$BE$5:$BN$5,0))} -> 0 | AP7: {=INDEX($BE$6:$BN$53,MATCH($AL7,$BD$6:$BD$53,0),MATCH(AP$5,$BE$5:$BN$5,0))} -> 0 | AQ7: {=INDEX($BE$6:$BN$53,MATCH($AL7,$BD$6:$BD$53,0),MATCH(AQ$5,$BE$5:$BN$5,0))} -> 3 | AR7: {=INDEX($BE$6:$BN$53,MATCH($AL7,$BD$6:$BD$53,0),MATCH(AR$5,$BE$5:$BN$5,0))} -> 3 | AS7: {=INDEX($BE$6:$BN$53,MATCH($AL7,$BD$6:$BD$53,0),MATCH(AS$5,$BE$5:$BN$5,0))} -> 7 | AT7: {=INDEX($BE$6:$BN$53,MATCH($AL7,$BD$6:$BD$53,0),MATCH(AT$5,$BE$5:$BN$5,0))} -> -4 | AU7: {=INDEX($DL$6:$DL$53,MATCH(AI7,$DP$6:$DP$53,0))} -> 4 | AV7: {=INDEX($BD$6:$BD$53,MATCH(AI7,$BM$6:$BM$53,0))} -> Sudáfrica | AY7: {=A6} -> Sudáfrica | BC7: A | BD7: Sudáfrica | BE7: {=BG7*3+BH7+IF($AZ$3="No",0,INDEX($AZ$6:$AZ$97,MATCH(BD7,$AY$6:$AY$97,0)))} -> 0 | BF7: {=BG7+BH7+BI7} -> 3 | BG7: {=COUNTIFS($AA$4:$AA$97,BD7,$D$4:$D$97,"Local")+COUNTIFS($AF$4:$AF$97,BD7,$D$4:$D$97,"Visitante")} -> 0 | BH7: {=COUNTIFS($AA$4:$AA$97,BD7,$D$4:$D$97,"Empate")+COUNTIFS($AF$4:$AF$97,BD7,$D$4:$D$97,"Empate")} -> 0 | BI7: {=COUNTIFS($AF$4:$AF$97,BD7,$D$4:$D$97,"Local")+COUNTIFS($AA$4:$AA$97,BD7,$D$4:$D$97,"Visitante")} -> 3 | BJ7: {=SUMIFS($AC$4:$AC$97,$AA$4:$AA$97,BD7,$D$4:$D$97,"<>"&"Pendiente",$AC$4:$AC$97,"<>"&"",$AD$4:$AD$97,"<>"&"")+SUMIFS($AD$4:$AD$97,$AF$4:$AF$97,BD7,$D$4:$D$97,"<>"&"Pendiente",$AC$4:$AC$97,"<>"&"",$AD$4:$AD$97,"<>"&"")} -> 3 | BK7: {=SUMIFS($AC$4:$AC$97,$AF$4:$AF$97,BD7,$D$4:$D$97,"<>"&"Pendiente",$AC$4:$AC$97,"<>"&"",$AD$4:$AD$97,"<>"&"")+SUMIFS($AD$4:$AD$97,$AA$4:$AA$97,BD7,$D$4:$D$97,"<>"&"Pendiente",$AC$4:$AC$97,"<>"&"",$AD$4:$AD$97,"<>"&"")} -> 7 | BL7: {=BJ7-BK7} -> -4 | BM7: {=DD7&BC7} -> 2A | BN7: {=DH7&BC7} -> 2A | BO7: {=IF(AND($AJ$99=144,BF7>=1),1,0)} -> 0 | BP7: 1 | BQ7: P.1 (4) | BR7: {=IF($BQ7="-","-",BE7)} -> 0 | BS7: 1 | BT7: P.1 (4) | BU7: {=IF($BT7="-","-",COUNTIFS($AA$4:$AA$97,$BD7,$D$4:$D$97,"Local",$F$4:$F$97,$BT7)+COUNTIFS($AF$4:$AF$97,$BD7,$D$4:$D$97,"Visitante",$E$4:$E$97,$BT7))} -> 0 | BV7: {=IF($BT7="-","-",COUNTIFS($AA$4:$AA$97,$BD7,$D$4:$D$97,"Empate",$F$4:$F$97,$BT7)+COUNTIFS($AF$4:$AF$97,$BD7,$D$4:$D$97,"Empate",$E$4:$E$97,$BT7))} -> 0 | BW7: {=IF($BT7="-","-",COUNTIFS($AA$4:$AA$97,$BD7,$D$4:$D$97,"Visitante",$F$4:$F$97,$BT7)+COUNTIFS($AF$4:$AF$97,$BD7,$D$4:$D$97,"Local",$E$4:$E$97,$BT7))} -> 3 | BX7: {=IF($BT7="-","-",BU7*3+BV7)} -> 0 | BY7: 1 | BZ7: P.1 (4) | CA7: {=IF($BZ7="-","-",SUMIFS($AC$4:$AC$97,$AA$4:$AA$97,$BD7,$I$4:$I$97,$BZ7)+SUMIFS($AD$4:$AD$97,$AF$4:$AF$97,$BD7,$H$4:$H$97,$BZ7))} -> 3 | CB7: {=IF($BZ7="-","-",SUMIFS($AD$4:$AD$97,$AA$4:$AA$97,$BD7,$I$4:$I$97,$BZ7)+SUMIFS($AC$4:$AC$97,$AF$4:$AF$97,$BD7,$H$4:$H$97,$BZ7))} -> 7 | CC7: {=IF($BZ7="-","-",CA7-CB7)} -> -4 | CD7: 1 | CE7: P.1 (4) | CF7: {=IF($CE7="-","-",SUMIFS($AC$4:$AC$97,$AA$4:$AA$97,$BD7,$L$4:$L$97,$CE7)+SUMIFS($AD$4:$AD$97,$AF$4:$AF$97,$BD7,$K$4:$K$97,$CE7))} -> 3 | CG7: 1 | CH7: P.1 (4) | CI7: {=IF($CH7="-","-",COUNTIFS($AA$4:$AA$97,$BD7,$D$4:$D$97,"Local",$O$4:$O$97,$CH7)+COUNTIFS($AF$4:$AF$97,$BD7,$D$4:$D$97,"Visitante",$N$4:$N$97,$CH7))} -> 0 | CJ7: {=IF($CH7="-","-",COUNTIFS($AA$4:$AA$97,$BD7,$D$4:$D$97,"Empate",$O$4:$O$97,$CH7)+COUNTIFS($AF$4:$AF$97,$BD7,$D$4:$D$97,"Empate",$N$4:$N$97,$CH7))} -> 0 | CK7: {=IF($CH7="-","-",COUNTIFS($AA$4:$AA$97,$BD7,$D$4:$D$97,"Visitante",$O$4:$O$97,$CH7)+COUNTIFS($AF$4:$AF$97,$BD7,$D$4:$D$97,"Local",$N$4:$N$97,$CH7))} -> 3 | CL7: {=IF($CH7="-","-",CI7*3+CJ7)} -> 0 | CM7: 1 | CN7: P.1 (4) | CO7: {=IF($CN7="-","-",SUMIFS($AC$4:$AC$97,$AA$4:$AA$97,$BD7,$R$4:$R$97,$CN7)+SUMIFS($AD$4:$AD$97,$AF$4:$AF$97,$BD7,$Q$4:$Q$97,$CN7))} -> 3 | CP7: {=IF($CN7="-","-",SUMIFS($AD$4:$AD$97,$AA$4:$AA$97,$BD7,$R$4:$R$97,$CN7)+SUMIFS($AC$4:$AC$97,$AF$4:$AF$97,$BD7,$Q$4:$Q$97,$CN7))} -> 7 | CQ7: {=IF($CN7="-","-",CO7-CP7)} -> -4 | CR7: 1 | CS7: P.1 (4) | CT7: {=IF($CS7="-","-",SUMIFS($AC$4:$AC$97,$AA$4:$AA$97,$BD7,$U$4:$U$97,$CS7)+SUMIFS($AD$4:$AD$97,$AF$4:$AF$97,$BD7,$T$4:$T$97,$CS7))} -> 3 | CU7: 1 | CV7: P.1 (4) | CW7: {=IF(CV7="-","-",BL7)} -> -4 | CX7: 1 | CY7: P.1 (4) | CZ7: {=IF(CY7="-","-",BJ7)} -> 3 | DA7: 1 | DB7: P.1 (4) | DC7: 2 | DD7: 2 | DF7: {=IF(OR(INDEX($AW$6:$AW$97,MATCH($BD7,$AV$6:$AV$97,0))="",DB7="-"),DD7,INDEX($AW$6:$AW$97,MATCH($BD7,$AV$6:$AV$97,0))+DD7/1000)} -> 2 | DG7: 1 | DH7: 2 | DJ7: {=INDEX($DA$6:$DA$53,MATCH($DQ7,$BD$6:$BD$53,0))} -> 1 | DK7: {=SUMIF($BC$6:$BC$53,BC7,$BF$6:$BF$53)} -> 12 | DL7: {=IF(OR(DK7=12,$AJ$99=144),COUNTIFS($DJ$6:$DJ$53,DJ7,$BC$6:$BC$53,BC7),1)} -> 4 | DM7: {=DJ7&"."&DL7} -> 1.4 | DN7: 1 | DP7: 2A | DQ7: {=INDEX($BD$6:$BD$53,MATCH(DP7,$BM$6:$BM$53,0))} -> Sudáfrica
A8: República Checa | D8: {=IF(OR(AC8="",AD8=""),"Pendiente",IF(AC8>AD8,"Local",IF(AC8<AD8,"Visitante","Empate")))} -> Visitante | E8: {=IF(D8="Pendiente","-",INDEX($BT$6:$BT$53,MATCH($AA8,$BD$6:$BD$53,0)))} -> P.1 (4) | F8: {=IF(D8="Pendiente","-",INDEX($BT$6:$BT$53,MATCH($AF8,$BD$6:$BD$53,0)))} -> P.1 (4) | H8: {=IF(D8="Pendiente","-",INDEX($BZ$6:$BZ$53,MATCH($AA8,$BD$6:$BD$53,0)))} -> P.1 (4) | I8: {=IF(D8="Pendiente","-",INDEX($BZ$6:$BZ$53,MATCH($AF8,$BD$6:$BD$53,0)))} -> P.1 (4) | K8: {=IF(D8="Pendiente","-",INDEX($CE$6:$CE$53,MATCH($AA8,$BD$6:$BD$53,0)))} -> P.1 (4) | L8: {=IF(D8="Pendiente","-",INDEX($CE$6:$CE$53,MATCH($AF8,$BD$6:$BD$53,0)))} -> P.1 (4) | N8: {=IF(D8="Pendiente","-",INDEX($CH$6:$CH$53,MATCH($AA8,$BD$6:$BD$53,0)))} -> P.1 (4) | O8: {=IF(D8="Pendiente","-",INDEX($CH$6:$CH$53,MATCH($AF8,$BD$6:$BD$53,0)))} -> P.1 (4) | Q8: {=IF(D8="Pendiente","-",INDEX($CN$6:$CN$53,MATCH($AA8,$BD$6:$BD$53,0)))} -> P.1 (4) | R8: {=IF(D8="Pendiente","-",INDEX($CN$6:$CN$53,MATCH($AF8,$BD$6:$BD$53,0)))} -> P.1 (4) | T8: {=IF(D8="Pendiente","-",INDEX($CS$6:$CS$53,MATCH($AA8,$BD$6:$BD$53,0)))} -> P.1 (4) | U8: {=IF(D8="Pendiente","-",INDEX($CS$6:$CS$53,MATCH($AF8,$BD$6:$BD$53,0)))} -> P.1 (4) | X8: 46197.875 | Y8: 46197.875 | Z8: J3 | AA8: {=A8} -> República Checa | AC8: 0 | AD8: 3 | AF8: {=A5} -> México | AG8: {=IF(NOT(OR(ISBLANK(AC8),ISBLANK(AD8))),1,0)} -> 1 | AH8: 53 | AI8: {=AJ8&$B$4} -> 3A | AJ8: 3 | AL8: {=IFERROR(INDEX($BD$6:$BD$53,MATCH(AI8,$BN$6:$BN$53,0)),"")} -> Corea del Sur | AM8: {=INDEX($BE$6:$BN$53,MATCH($AL8,$BD$6:$BD$53,0),MATCH(AM$5,$BE$5:$BN$5,0))} -> 6 | AN8: {=INDEX($BE$6:$BN$53,MATCH($AL8,$BD$6:$BD$53,0),MATCH(AN$5,$BE$5:$BN$5,0))} -> 3 | AO8: {=INDEX($BE$6:$BN$53,MATCH($AL8,$BD$6:$BD$53,0),MATCH(AO$5,$BE$5:$BN$5,0))} -> 2 | AP8: {=INDEX($BE$6:$BN$53,MATCH($AL8,$BD$6:$BD$53,0),MATCH(AP$5,$BE$5:$BN$5,0))} -> 0 | AQ8: {=INDEX($BE$6:$BN$53,MATCH($AL8,$BD$6:$BD$53,0),MATCH(AQ$5,$BE$5:$BN$5,0))} -> 1 | AR8: {=INDEX($BE$6:$BN$53,MATCH($AL8,$BD$6:$BD$53,0),MATCH(AR$5,$BE$5:$BN$5,0))} -> 6 | AS8: {=INDEX($BE$6:$BN$53,MATCH($AL8,$BD$6:$BD$53,0),MATCH(AS$5,$BE$5:$BN$5,0))} -> 4 | AT8: {=INDEX($BE$6:$BN$53,MATCH($AL8,$BD$6:$BD$53,0),MATCH(AT$5,$BE$5:$BN$5,0))} -> 2 | AU8: {=INDEX($DL$6:$DL$53,MATCH(AI8,$DP$6:$DP$53,0))} -> 4 | AV8: {=INDEX($BD$6:$BD$53,MATCH(AI8,$BM$6:$BM$53,0))} -> Corea del Sur | AY8: {=A7} -> Corea del Sur | BC8: A | BD8: Corea del Sur | BE8: {=BG8*3+BH8+IF($AZ$3="No",0,INDEX($AZ$6:$AZ$97,MATCH(BD8,$AY$6:$AY$97,0)))} -> 6 | BF8: {=BG8+BH8+BI8} -> 3 | BG8: {=COUNTIFS($AA$4:$AA$97,BD8,$D$4:$D$97,"Local")+COUNTIFS($AF$4:$AF$97,BD8,$D$4:$D$97,"Visitante")} -> 2 | BH8: {=COUNTIFS($AA$4:$AA$97,BD8,$D$4:$D$97,"Empate")+COUNTIFS($AF$4:$AF$97,BD8,$D$4:$D$97,"Empate")} -> 0 | BI8: {=COUNTIFS($AF$4:$AF$97,BD8,$D$4:$D$97,"Local")+COUNTIFS($AA$4:$AA$97,BD8,$D$4:$D$97,"Visitante")} -> 1 | BJ8: {=SUMIFS($AC$4:$AC$97,$AA$4:$AA$97,BD8,$D$4:$D$97,"<>"&"Pendiente",$AC$4:$AC$97,"<>"&"",$AD$4:$AD$97,"<>"&"")+SUMIFS($AD$4:$AD$97,$AF$4:$AF$97,BD8,$D$4:$D$97,"<>"&"Pendiente",$AC$4:$AC$97,"<>"&"",$AD$4:$AD$97,"<>"&"")} -> 6 | BK8: {=SUMIFS($AC$4:$AC$97,$AF$4:$AF$97,BD8,$D$4:$D$97,"<>"&"Pendiente",$AC$4:$AC$97,"<>"&"",$AD$4:$AD$97,"<>"&"")+SUMIFS($AD$4:$AD$97,$AA$4:$AA$97,BD8,$D$4:$D$97,"<>"&"Pendiente",$AC$4:$AC$97,"<>"&"",$AD$4:$AD$97,"<>"&"")} -> 4 | BL8: {=BJ8-BK8} -> 2 | BM8: {=DD8&BC8} -> 3A | BN8: {=DH8&BC8} -> 3A | BO8: {=IF(AND($AJ$99=144,BF8>=1),1,0)} -> 0 | BP8: 1 | BQ8: P.1 (4) | BR8: {=IF($BQ8="-","-",BE8)} -> 6 | BS8: 1 | BT8: P.1 (4) | BU8: {=IF($BT8="-","-",COUNTIFS($AA$4:$AA$97,$BD8,$D$4:$D$97,"Local",$F$4:$F$97,$BT8)+COUNTIFS($AF$4:$AF$97,$BD8,$D$4:$D$97,"Visitante",$E$4:$E$97,$BT8))} -> 2 | BV8: {=IF($BT8="-","-",COUNTIFS($AA$4:$AA$97,$BD8,$D$4:$D$97,"Empate",$F$4:$F$97,$BT8)+COUNTIFS($AF$4:$AF$97,$BD8,$D$4:$D$97,"Empate",$E$4:$E$97,$BT8))} -> 0 | BW8: {=IF($BT8="-","-",COUNTIFS($AA$4:$AA$97,$BD8,$D$4:$D$97,"Visitante",$F$4:$F$97,$BT8)+COUNTIFS($AF$4:$AF$97,$BD8,$D$4:$D$97,"Local",$E$4:$E$97,$BT8))} -> 1 | BX8: {=IF($BT8="-","-",BU8*3+BV8)} -> 6 | BY8: 1 | BZ8: P.1 (4) | CA8: {=IF($BZ8="-","-",SUMIFS($AC$4:$AC$97,$AA$4:$AA$97,$BD8,$I$4:$I$97,$BZ8)+SUMIFS($AD$4:$AD$97,$AF$4:$AF$97,$BD8,$H$4:$H$97,$BZ8))} -> 6 | CB8: {=IF($BZ8="-","-",SUMIFS($AD$4:$AD$97,$AA$4:$AA$97,$BD8,$I$4:$I$97,$BZ8)+SUMIFS($AC$4:$AC$97,$AF$4:$AF$97,$BD8,$H$4:$H$97,$BZ8))} -> 4 | CC8: {=IF($BZ8="-","-",CA8-CB8)} -> 2 | CD8: 1 | CE8: P.1 (4) | CF8: {=IF($CE8="-","-",SUMIFS($AC$4:$AC$97,$AA$4:$AA$97,$BD8,$L$4:$L$97,$CE8)+SUMIFS($AD$4:$AD$97,$AF$4:$AF$97,$BD8,$K$4:$K$97,$CE8))} -> 6 | CG8: 1 | CH8: P.1 (4) | CI8: {=IF($CH8="-","-",COUNTIFS($AA$4:$AA$97,$BD8,$D$4:$D$97,"Local",$O$4:$O$97,$CH8)+COUNTIFS($AF$4:$AF$97,$BD8,$D$4:$D$97,"Visitante",$N$4:$N$97,$CH8))} -> 2 | CJ8: {=IF($CH8="-","-",COUNTIFS($AA$4:$AA$97,$BD8,$D$4:$D$97,"Empate",$O$4:$O$97,$CH8)+COUNTIFS($AF$4:$AF$97,$BD8,$D$4:$D$97,"Empate",$N$4:$N$97,$CH8))} -> 0 | CK8: {=IF($CH8="-","-",COUNTIFS($AA$4:$AA$97,$BD8,$D$4:$D$97,"Visitante",$O$4:$O$97,$CH8)+COUNTIFS($AF$4:$AF$97,$BD8,$D$4:$D$97,"Local",$N$4:$N$97,$CH8))} -> 1 | CL8: {=IF($CH8="-","-",CI8*3+CJ8)} -> 6 | CM8: 1 | CN8: P.1 (4) | CO8: {=IF($CN8="-","-",SUMIFS($AC$4:$AC$97,$AA$4:$AA$97,$BD8,$R$4:$R$97,$CN8)+SUMIFS($AD$4:$AD$97,$AF$4:$AF$97,$BD8,$Q$4:$Q$97,$CN8))} -> 6 | CP8: {=IF($CN8="-","-",SUMIFS($AD$4:$AD$97,$AA$4:$AA$97,$BD8,$R$4:$R$97,$CN8)+SUMIFS($AC$4:$AC$97,$AF$4:$AF$97,$BD8,$Q$4:$Q$97,$CN8))} -> 4 | CQ8: {=IF($CN8="-","-",CO8-CP8)} -> 2 | CR8: 1 | CS8: P.1 (4) | CT8: {=IF($CS8="-","-",SUMIFS($AC$4:$AC$97,$AA$4:$AA$97,$BD8,$U$4:$U$97,$CS8)+SUMIFS($AD$4:$AD$97,$AF$4:$AF$97,$BD8,$T$4:$T$97,$CS8))} -> 6 | CU8: 1 | CV8: P.1 (4) | CW8: {=IF(CV8="-","-",BL8)} -> 2 | CX8: 1 | CY8: P.1 (4) | CZ8: {=IF(CY8="-","-",BJ8)} -> 6 | DA8: 1 | DB8: P.1 (4) | DC8: 3 | DD8: 3 | DF8: {=IF(OR(INDEX($AW$6:$AW$97,MATCH($BD8,$AV$6:$AV$97,0))="",DB8="-"),DD8,INDEX($AW$6:$AW$97,MATCH($BD8,$AV$6:$AV$97,0))+DD8/1000)} -> 3 | DG8: 2 | DH8: 3 | DJ8: {=INDEX($DA$6:$DA$53,MATCH($DQ8,$BD$6:$BD$53,0))} -> 1 | DK8: {=SUMIF($BC$6:$BC$53,BC8,$BF$6:$BF$53)} -> 12 | DL8: {=IF(OR(DK8=12,$AJ$99=144),COUNTIFS($DJ$6:$DJ$53,DJ8,$BC$6:$BC$53,BC8),1)} -> 4 | DM8: {=DJ8&"."&DL8} -> 1.4 | DN8: 1 | DP8: 3A | DQ8: {=INDEX($BD$6:$BD$53,MATCH(DP8,$BM$6:$BM$53,0))} -> Corea del Sur
D9: {=IF(OR(AC9="",AD9=""),"Pendiente",IF(AC9>AD9,"Local",IF(AC9<AD9,"Visitante","Empate")))} -> Visitante | E9: {=IF(D9="Pendiente","-",INDEX($BT$6:$BT$53,MATCH($AA9,$BD$6:$BD$53,0)))} -> P.1 (4) | F9: {=IF(D9="Pendiente","-",INDEX($BT$6:$BT$53,MATCH($AF9,$BD$6:$BD$53,0)))} -> P.1 (4) | H9: {=IF(D9="Pendiente","-",INDEX($BZ$6:$BZ$53,MATCH($AA9,$BD$6:$BD$53,0)))} -> P.1 (4) | I9: {=IF(D9="Pendiente","-",INDEX($BZ$6:$BZ$53,MATCH($AF9,$BD$6:$BD$53,0)))} -> P.1 (4) | K9: {=IF(D9="Pendiente","-",INDEX($CE$6:$CE$53,MATCH($AA9,$BD$6:$BD$53,0)))} -> P.1 (4) | L9: {=IF(D9="Pendiente","-",INDEX($CE$6:$CE$53,MATCH($AF9,$BD$6:$BD$53,0)))} -> P.1 (4) | N9: {=IF(D9="Pendiente","-",INDEX($CH$6:$CH$53,MATCH($AA9,$BD$6:$BD$53,0)))} -> P.1 (4) | O9: {=IF(D9="Pendiente","-",INDEX($CH$6:$CH$53,MATCH($AF9,$BD$6:$BD$53,0)))} -> P.1 (4) | Q9: {=IF(D9="Pendiente","-",INDEX($CN$6:$CN$53,MATCH($AA9,$BD$6:$BD$53,0)))} -> P.1 (4) | R9: {=IF(D9="Pendiente","-",INDEX($CN$6:$CN$53,MATCH($AF9,$BD$6:$BD$53,0)))} -> P.1 (4) | T9: {=IF(D9="Pendiente","-",INDEX($CS$6:$CS$53,MATCH($AA9,$BD$6:$BD$53,0)))} -> P.1 (4) | U9: {=IF(D9="Pendiente","-",INDEX($CS$6:$CS$53,MATCH($AF9,$BD$6:$BD$53,0)))} -> P.1 (4) | X9: 46197.875 | Y9: 46197.875 | Z9: {=$Z$8} -> J3 | AA9: {=A6} -> Sudáfrica | AC9: 1 | AD9: 3 | AF9: {=A7} -> Corea del Sur | AG9: {=IF(NOT(OR(ISBLANK(AC9),ISBLANK(AD9))),1,0)} -> 1 | AH9: 54 | AI9: {=AJ9&$B$4} -> 4A | AJ9: 4 | AL9: {=IFERROR(INDEX($BD$6:$BD$53,MATCH(AI9,$BN$6:$BN$53,0)),"")} -> República Checa | AM9: {=INDEX($BE$6:$BN$53,MATCH($AL9,$BD$6:$BD$53,0),MATCH(AM$5,$BE$5:$BN$5,0))} -> 3 | AN9: {=INDEX($BE$6:$BN$53,MATCH($AL9,$BD$6:$BD$53,0),MATCH(AN$5,$BE$5:$BN$5,0))} -> 3 | AO9: {=INDEX($BE$6:$BN$53,MATCH($AL9,$BD$6:$BD$53,0),MATCH(AO$5,$BE$5:$BN$5,0))} -> 1 | AP9: {=INDEX($BE$6:$BN$53,MATCH($AL9,$BD$6:$BD$53,0),MATCH(AP$5,$BE$5:$BN$5,0))} -> 0 | AQ9: {=INDEX($BE$6:$BN$53,MATCH($AL9,$BD$6:$BD$53,0),MATCH(AQ$5,$BE$5:$BN$5,0))} -> 2 | AR9: {=INDEX($BE$6:$BN$53,MATCH($AL9,$BD$6:$BD$53,0),MATCH(AR$5,$BE$5:$BN$5,0))} -> 3 | AS9: {=INDEX($BE$6:$BN$53,MATCH($AL9,$BD$6:$BD$53,0),MATCH(AS$5,$BE$5:$BN$5,0))} -> 6 | AT9: {=INDEX($BE$6:$BN$53,MATCH($AL9,$BD$6:$BD$53,0),MATCH(AT$5,$BE$5:$BN$5,0))} -> -3 | AU9: {=INDEX($DL$6:$DL$53,MATCH(AI9,$DP$6:$DP$53,0))} -> 4 | AV9: {=INDEX($BD$6:$BD$53,MATCH(AI9,$BM$6:$BM$53,0))} -> República Checa | AY9: {=A8} -> República Checa | BC9: A | BD9: República Checa | BE9: {=BG9*3+BH9+IF($AZ$3="No",0,INDEX($AZ$6:$AZ$97,MATCH(BD9,$AY$6:$AY$97,0)))} -> 3 | BF9: {=BG9+BH9+BI9} -> 3 | BG9: {=COUNTIFS($AA$4:$AA$97,BD9,$D$4:$D$97,"Local")+COUNTIFS($AF$4:$AF$97,BD9,$D$4:$D$97,"Visitante")} -> 1 | BH9: {=COUNTIFS($AA$4:$AA$97,BD9,$D$4:$D$97,"Empate")+COUNTIFS($AF$4:$AF$97,BD9,$D$4:$D$97,"Empate")} -> 0 | BI9: {=COUNTIFS($AF$4:$AF$97,BD9,$D$4:$D$97,"Local")+COUNTIFS($AA$4:$AA$97,BD9,$D$4:$D$97,"Visitante")} -> 2 | BJ9: {=SUMIFS($AC$4:$AC$97,$AA$4:$AA$97,BD9,$D$4:$D$97,"<>"&"Pendiente",$AC$4:$AC$97,"<>"&"",$AD$4:$AD$97,"<>"&"")+SUMIFS($AD$4:$AD$97,$AF$4:$AF$97,BD9,$D$4:$D$97,"<>"&"Pendiente",$AC$4:$AC$97,"<>"&"",$AD$4:$AD$97,"<>"&"")} -> 3 | BK9: {=SUMIFS($AC$4:$AC$97,$AF$4:$AF$97,BD9,$D$4:$D$97,"<>"&"Pendiente",$AC$4:$AC$97,"<>"&"",$AD$4:$AD$97,"<>"&"")+SUMIFS($AD$4:$AD$97,$AA$4:$AA$97,BD9,$D$4:$D$97,"<>"&"Pendiente",$AC$4:$AC$97,"<>"&"",$AD$4:$AD$97,"<>"&"")} -> 6 | BL9: {=BJ9-BK9} -> -3 | BM9: {=DD9&BC9} -> 4A | BN9: {=DH9&BC9} -> 4A | BO9: {=IF(AND($AJ$99=144,BF9>=1),1,0)} -> 0 | BP9: 1 | BQ9: P.1 (4) | BR9: {=IF($BQ9="-","-",BE9)} -> 3 | BS9: 1 | BT9: P.1 (4) | BU9: {=IF($BT9="-","-",COUNTIFS($AA$4:$AA$97,$BD9,$D$4:$D$97,"Local",$F$4:$F$97,$BT9)+COUNTIFS($AF$4:$AF$97,$BD9,$D$4:$D$97,"Visitante",$E$4:$E$97,$BT9))} -> 1 | BV9: {=IF($BT9="-","-",COUNTIFS($AA$4:$AA$97,$BD9,$D$4:$D$97,"Empate",$F$4:$F$97,$BT9)+COUNTIFS($AF$4:$AF$97,$BD9,$D$4:$D$97,"Empate",$E$4:$E$97,$BT9))} -> 0 | BW9: {=IF($BT9="-","-",COUNTIFS($AA$4:$AA$97,$BD9,$D$4:$D$97,"Visitante",$F$4:$F$97,$BT9)+COUNTIFS($AF$4:$AF$97,$BD9,$D$4:$D$97,"Local",$E$4:$E$97,$BT9))} -> 2 | BX9: {=IF($BT9="-","-",BU9*3+BV9)} -> 3 | BY9: 1 | BZ9: P.1 (4) | CA9: {=IF($BZ9="-","-",SUMIFS($AC$4:$AC$97,$AA$4:$AA$97,$BD9,$I$4:$I$97,$BZ9)+SUMIFS($AD$4:$AD$97,$AF$4:$AF$97,$BD9,$H$4:$H$97,$BZ9))} -> 3 | CB9: {=IF($BZ9="-","-",SUMIFS($AD$4:$AD$97,$AA$4:$AA$97,$BD9,$I$4:$I$97,$BZ9)+SUMIFS($AC$4:$AC$97,$AF$4:$AF$97,$BD9,$H$4:$H$97,$BZ9))} -> 6 | CC9: {=IF($BZ9="-","-",CA9-CB9)} -> -3 | CD9: 1 | CE9: P.1 (4) | CF9: {=IF($CE9="-","-",SUMIFS($AC$4:$AC$97,$AA$4:$AA$97,$BD9,$L$4:$L$97,$CE9)+SUMIFS($AD$4:$AD$97,$AF$4:$AF$97,$BD9,$K$4:$K$97,$CE9))} -> 3 | CG9: 1 | CH9: P.1 (4) | CI9: {=IF($CH9="-","-",COUNTIFS($AA$4:$AA$97,$BD9,$D$4:$D$97,"Local",$O$4:$O$97,$CH9)+COUNTIFS($AF$4:$AF$97,$BD9,$D$4:$D$97,"Visitante",$N$4:$N$97,$CH9))} -> 1 | CJ9: {=IF($CH9="-","-",COUNTIFS($AA$4:$AA$97,$BD9,$D$4:$D$97,"Empate",$O$4:$O$97,$CH9)+COUNTIFS($AF$4:$AF$97,$BD9,$D$4:$D$97,"Empate",$N$4:$N$97,$CH9))} -> 0 | CK9: {=IF($CH9="-","-",COUNTIFS($AA$4:$AA$97,$BD9,$D$4:$D$97,"Visitante",$O$4:$O$97,$CH9)+COUNTIFS($AF$4:$AF$97,$BD9,$D$4:$D$97,"Local",$N$4:$N$97,$CH9))} -> 2 | CL9: {=IF($CH9="-","-",CI9*3+CJ9)} -> 3 | CM9: 1 | CN9: P.1 (4) | CO9: {=IF($CN9="-","-",SUMIFS($AC$4:$AC$97,$AA$4:$AA$97,$BD9,$R$4:$R$97,$CN9)+SUMIFS($AD$4:$AD$97,$AF$4:$AF$97,$BD9,$Q$4:$Q$97,$CN9))} -> 3 | CP9: {=IF($CN9="-","-",SUMIFS($AD$4:$AD$97,$AA$4:$AA$97,$BD9,$R$4:$R$97,$CN9)+SUMIFS($AC$4:$AC$97,$AF$4:$AF$97,$BD9,$Q$4:$Q$97,$CN9))} -> 6 | CQ9: {=IF($CN9="-","-",CO9-CP9)} -> -3 | CR9: 1 | CS9: P.1 (4) | CT9: {=IF($CS9="-","-",SUMIFS($AC$4:$AC$97,$AA$4:$AA$97,$BD9,$U$4:$U$97,$CS9)+SUMIFS($AD$4:$AD$97,$AF$4:$AF$97,$BD9,$T$4:$T$97,$CS9))} -> 3 | CU9: 1 | CV9: P.1 (4) | CW9: {=IF(CV9="-","-",BL9)} -> -3 | CX9: 1 | CY9: P.1 (4) | CZ9: {=IF(CY9="-","-",BJ9)} -> 3 | DA9: 1 | DB9: P.1 (4) | DC9: 4 | DD9: 4 | DF9: {=IF(OR(INDEX($AW$6:$AW$97,MATCH($BD9,$AV$6:$AV$97,0))="",DB9="-"),DD9,INDEX($AW$6:$AW$97,MATCH($BD9,$AV$6:$AV$97,0))+DD9/1000)} -> 4 | DG9: 3 | DH9: 4 | DJ9: {=INDEX($DA$6:$DA$53,MATCH($DQ9,$BD$6:$BD$53,0))} -> 1 | DK9: {=SUMIF($BC$6:$BC$53,BC9,$BF$6:$BF$53)} -> 12 | DL9: {=IF(OR(DK9=12,$AJ$99=144),COUNTIFS($DJ$6:$DJ$53,DJ9,$BC$6:$BC$53,BC9),1)} -> 4 | DM9: {=DJ9&"."&DL9} -> 1.4 | DN9: 1 | DP9: 4A | DQ9: {=INDEX($BD$6:$BD$53,MATCH(DP9,$BM$6:$BM$53,0))} -> República Checa
BC10: B | BD10: Canadá | BE10: {=BG10*3+BH10+IF($AZ$3="No",0,INDEX($AZ$6:$AZ$97,MATCH(BD10,$AY$6:$AY$97,0)))} -> 7 | BF10: {=BG10+BH10+BI10} -> 3 | BG10: {=COUNTIFS($AA$4:$AA$97,BD10,$D$4:$D$97,"Local")+COUNTIFS($AF$4:$AF$97,BD10,$D$4:$D$97,"Visitante")} -> 2 | BH10: {=COUNTIFS($AA$4:$AA$97,BD10,$D$4:$D$97,"Empate")+COUNTIFS($AF$4:$AF$97,BD10,$D$4:$D$97,"Empate")} -> 1 | BI10: {=COUNTIFS($AF$4:$AF$97,BD10,$D$4:$D$97,"Local")+COUNTIFS($AA$4:$AA$97,BD10,$D$4:$D$97,"Visitante")} -> 0 | BJ10: {=SUMIFS($AC$4:$AC$97,$AA$4:$AA$97,BD10,$D$4:$D$97,"<>"&"Pendiente",$AC$4:$AC$97,"<>"&"",$AD$4:$AD$97,"<>"&"")+SUMIFS($AD$4:$AD$97,$AF$4:$AF$97,BD10,$D$4:$D$97,"<>"&"Pendiente",$AC$4:$AC$97,"<>"&"",$AD$4:$AD$97,"<>"&"")} -> 4 | BK10: {=SUMIFS($AC$4:$AC$97,$AF$4:$AF$97,BD10,$D$4:$D$97,"<>"&"Pendiente",$AC$4:$AC$97,"<>"&"",$AD$4:$AD$97,"<>"&"")+SUMIFS($AD$4:$AD$97,$AA$4:$AA$97,BD10,$D$4:$D$97,"<>"&"Pendiente",$AC$4:$AC$97,"<>"&"",$AD$4:$AD$97,"<>"&"")} -> 2 | BL10: {=BJ10-BK10} -> 2 | BM10: {=DD10&BC10} -> 1B | BN10: {=DH10&BC10} -> 1B | BO10: {=IF(AND($AJ$99=144,BF10>=1),1,0)} -> 0 | BP10: 1 | BQ10: P.1 (4) | BR10: {=IF($BQ10="-","-",BE10)} -> 7 | BS10: 1 | BT10: P.1 (4) | BU10: {=IF($BT10="-","-",COUNTIFS($AA$4:$AA$97,$BD10,$D$4:$D$97,"Local",$F$4:$F$97,$BT10)+COUNTIFS($AF$4:$AF$97,$BD10,$D$4:$D$97,"Visitante",$E$4:$E$97,$BT10))} -> 2 | BV10: {=IF($BT10="-","-",COUNTIFS($AA$4:$AA$97,$BD10,$D$4:$D$97,"Empate",$F$4:$F$97,$BT10)+COUNTIFS($AF$4:$AF$97,$BD10,$D$4:$D$97,"Empate",$E$4:$E$97,$BT10))} -> 1 | BW10: {=IF($BT10="-","-",COUNTIFS($AA$4:$AA$97,$BD10,$D$4:$D$97,"Visitante",$F$4:$F$97,$BT10)+COUNTIFS($AF$4:$AF$97,$BD10,$D$4:$D$97,"Local",$E$4:$E$97,$BT10))} -> 0 | BX10: {=IF($BT10="-","-",BU10*3+BV10)} -> 7 | BY10: 1 | BZ10: P.1 (4) | CA10: {=IF($BZ10="-","-",SUMIFS($AC$4:$AC$97,$AA$4:$AA$97,$BD10,$I$4:$I$97,$BZ10)+SUMIFS($AD$4:$AD$97,$AF$4:$AF$97,$BD10,$H$4:$H$97,$BZ10))} -> 4 | CB10: {=IF($BZ10="-","-",SUMIFS($AD$4:$AD$97,$AA$4:$AA$97,$BD10,$I$4:$I$97,$BZ10)+SUMIFS($AC$4:$AC$97,$AF$4:$AF$97,$BD10,$H$4:$H$97,$BZ10))} -> 2 | CC10: {=IF($BZ10="-","-",CA10-CB10)} -> 2 | CD10: 1 | CE10: P.1 (4) | CF10: {=IF($CE10="-","-",SUMIFS($AC$4:$AC$97,$AA$4:$AA$97,$BD10,$L$4:$L$97,$CE10)+SUMIFS($AD$4:$AD$97,$AF$4:$AF$97,$BD10,$K$4:$K$97,$CE10))} -> 4 | CG10: 1 | CH10: P.1 (4) | CI10: {=IF($CH10="-","-",COUNTIFS($AA$4:$AA$97,$BD10,$D$4:$D$97,"Local",$O$4:$O$97,$CH10)+COUNTIFS($AF$4:$AF$97,$BD10,$D$4:$D$97,"Visitante",$N$4:$N$97,$CH10))} -> 2 | CJ10: {=IF($CH10="-","-",COUNTIFS($AA$4:$AA$97,$BD10,$D$4:$D$97,"Empate",$O$4:$O$97,$CH10)+COUNTIFS($AF$4:$AF$97,$BD10,$D$4:$D$97,"Empate",$N$4:$N$97,$CH10))} -> 1 | CK10: {=IF($CH10="-","-",COUNTIFS($AA$4:$AA$97,$BD10,$D$4:$D$97,"Visitante",$O$4:$O$97,$CH10)+COUNTIFS($AF$4:$AF$97,$BD10,$D$4:$D$97,"Local",$N$4:$N$97,$CH10))} -> 0 | CL10: {=IF($CH10="-","-",CI10*3+CJ10)} -> 7 | CM10: 1 | CN10: P.1 (4) | CO10: {=IF($CN10="-","-",SUMIFS($AC$4:$AC$97,$AA$4:$AA$97,$BD10,$R$4:$R$97,$CN10)+SUMIFS($AD$4:$AD$97,$AF$4:$AF$97,$BD10,$Q$4:$Q$97,$CN10))} -> 4 | CP10: {=IF($CN10="-","-",SUMIFS($AD$4:$AD$97,$AA$4:$AA$97,$BD10,$R$4:$R$97,$CN10)+SUMIFS($AC$4:$AC$97,$AF$4:$AF$97,$BD10,$Q$4:$Q$97,$CN10))} -> 2 | CQ10: {=IF($CN10="-","-",CO10-CP10)} -> 2 | CR10: 1 | CS10: P.1 (4) | CT10: {=IF($CS10="-","-",SUMIFS($AC$4:$AC$97,$AA$4:$AA$97,$BD10,$U$4:$U$97,$CS10)+SUMIFS($AD$4:$AD$97,$AF$4:$AF$97,$BD10,$T$4:$T$97,$CS10))} -> 4 | CU10: 1 | CV10: P.1 (4) | CW10: {=IF(CV10="-","-",BL10)} -> 2 | CX10: 1 | CY10: P.1 (4) | CZ10: {=IF(CY10="-","-",BJ10)} -> 4 | DA10: 1 | DB10: P.1 (4) | DC10: 1 | DD10: 1 | DF10: {=IF(OR(INDEX($AW$6:$AW$97,MATCH($BD10,$AV$6:$AV$97,0))="",DB10="-"),DD10,INDEX($AW$6:$AW$97,MATCH($BD10,$AV$6:$AV$97,0))+DD10/1000)} -> 1 | DG10: 0 | DH10: 1 | DJ10: {=INDEX($DA$6:$DA$53,MATCH($DQ10,$BD$6:$BD$53,0))} -> 1 | DK10: {=SUMIF($BC$6:$BC$53,BC10,$BF$6:$BF$53)} -> 12 | DL10: {=IF(OR(DK10=12,$AJ$99=144),COUNTIFS($DJ$6:$DJ$53,DJ10,$BC$6:$BC$53,BC10),1)} -> 4 | DM10: {=DJ10&"."&DL10} -> 1.4 | DN10: 1 | DP10: 1B | DQ10: {=INDEX($BD$6:$BD$53,MATCH(DP10,$BM$6:$BM$53,0))} -> Canadá
X11: {=X3} -> Fecha | Y11: {=Y3} -> Hora | Z11: {=Z3} -> Jor. | AA11: {=AA3} -> Casa | AC11: {=AC3} -> Gol | AD11: {=AD3} -> Gol | AF11: {=AF3} -> Fuera | BC11: B | BD11: Bosnia y Herzegovina | BE11: {=BG11*3+BH11+IF($AZ$3="No",0,INDEX($AZ$6:$AZ$97,MATCH(BD11,$AY$6:$AY$97,0)))} -> 0 | BF11: {=BG11+BH11+BI11} -> 3 | BG11: {=COUNTIFS($AA$4:$AA$97,BD11,$D$4:$D$97,"Local")+COUNTIFS($AF$4:$AF$97,BD11,$D$4:$D$97,"Visitante")} -> 0 | BH11: {=COUNTIFS($AA$4:$AA$97,BD11,$D$4:$D$97,"Empate")+COUNTIFS($AF$4:$AF$97,BD11,$D$4:$D$97,"Empate")} -> 0 | BI11: {=COUNTIFS($AF$4:$AF$97,BD11,$D$4:$D$97,"Local")+COUNTIFS($AA$4:$AA$97,BD11,$D$4:$D$97,"Visitante")} -> 3 | BJ11: {=SUMIFS($AC$4:$AC$97,$AA$4:$AA$97,BD11,$D$4:$D$97,"<>"&"Pendiente",$AC$4:$AC$97,"<>"&"",$AD$4:$AD$97,"<>"&"")+SUMIFS($AD$4:$AD$97,$AF$4:$AF$97,BD11,$D$4:$D$97,"<>"&"Pendiente",$AC$4:$AC$97,"<>"&"",$AD$4:$AD$97,"<>"&"")} -> 1 | BK11: {=SUMIFS($AC$4:$AC$97,$AF$4:$AF$97,BD11,$D$4:$D$97,"<>"&"Pendiente",$AC$4:$AC$97,"<>"&"",$AD$4:$AD$97,"<>"&"")+SUMIFS($AD$4:$AD$97,$AA$4:$AA$97,BD11,$D$4:$D$97,"<>"&"Pendiente",$AC$4:$AC$97,"<>"&"",$AD$4:$AD$97,"<>"&"")} -> 5 | BL11: {=BJ11-BK11} -> -4 | BM11: {=DD11&BC11} -> 2B | BN11: {=DH11&BC11} -> 2B | BO11: {=IF(AND($AJ$99=144,BF11>=1),1,0)} -> 0 | BP11: 1 | BQ11: P.1 (4) | BR11: {=IF($BQ11="-","-",BE11)} -> 0 | BS11: 1 | BT11: P.1 (4) | BU11: {=IF($BT11="-","-",COUNTIFS($AA$4:$AA$97,$BD11,$D$4:$D$97,"Local",$F$4:$F$97,$BT11)+COUNTIFS($AF$4:$AF$97,$BD11,$D$4:$D$97,"Visitante",$E$4:$E$97,$BT11))} -> 0 | BV11: {=IF($BT11="-","-",COUNTIFS($AA$4:$AA$97,$BD11,$D$4:$D$97,"Empate",$F$4:$F$97,$BT11)+COUNTIFS($AF$4:$AF$97,$BD11,$D$4:$D$97,"Empate",$E$4:$E$97,$BT11))} -> 0 | BW11: {=IF($BT11="-","-",COUNTIFS($AA$4:$AA$97,$BD11,$D$4:$D$97,"Visitante",$F$4:$F$97,$BT11)+COUNTIFS($AF$4:$AF$97,$BD11,$D$4:$D$97,"Local",$E$4:$E$97,$BT11))} -> 3 | BX11: {=IF($BT11="-","-",BU11*3+BV11)} -> 0 | BY11: 1 | BZ11: P.1 (4) | CA11: {=IF($BZ11="-","-",SUMIFS($AC$4:$AC$97,$AA$4:$AA$97,$BD11,$I$4:$I$97,$BZ11)+SUMIFS($AD$4:$AD$97,$AF$4:$AF$97,$BD11,$H$4:$H$97,$BZ11))} -> 1 | CB11: {=IF($BZ11="-","-",SUMIFS($AD$4:$AD$97,$AA$4:$AA$97,$BD11,$I$4:$I$97,$BZ11)+SUMIFS($AC$4:$AC$97,$AF$4:$AF$97,$BD11,$H$4:$H$97,$BZ11))} -> 5 | CC11: {=IF($BZ11="-","-",CA11-CB11)} -> -4 | CD11: 1 | CE11: P.1 (4) | CF11: {=IF($CE11="-","-",SUMIFS($AC$4:$AC$97,$AA$4:$AA$97,$BD11,$L$4:$L$97,$CE11)+SUMIFS($AD$4:$AD$97,$AF$4:$AF$97,$BD11,$K$4:$K$97,$CE11))} -> 1 | CG11: 1 | CH11: P.1 (4) | CI11: {=IF($CH11="-","-",COUNTIFS($AA$4:$AA$97,$BD11,$D$4:$D$97,"Local",$O$4:$O$97,$CH11)+COUNTIFS($AF$4:$AF$97,$BD11,$D$4:$D$97,"Visitante",$N$4:$N$97,$CH11))} -> 0 | CJ11: {=IF($CH11="-","-",COUNTIFS($AA$4:$AA$97,$BD11,$D$4:$D$97,"Empate",$O$4:$O$97,$CH11)+COUNTIFS($AF$4:$AF$97,$BD11,$D$4:$D$97,"Empate",$N$4:$N$97,$CH11))} -> 0 | CK11: {=IF($CH11="-","-",COUNTIFS($AA$4:$AA$97,$BD11,$D$4:$D$97,"Visitante",$O$4:$O$97,$CH11)+COUNTIFS($AF$4:$AF$97,$BD11,$D$4:$D$97,"Local",$N$4:$N$97,$CH11))} -> 3 | CL11: {=IF($CH11="-","-",CI11*3+CJ11)} -> 0 | CM11: 1 | CN11: P.1 (4) | CO11: {=IF($CN11="-","-",SUMIFS($AC$4:$AC$97,$AA$4:$AA$97,$BD11,$R$4:$R$97,$CN11)+SUMIFS($AD$4:$AD$97,$AF$4:$AF$97,$BD11,$Q$4:$Q$97,$CN11))} -> 1 | CP11: {=IF($CN11="-","-",SUMIFS($AD$4:$AD$97,$AA$4:$AA$97,$BD11,$R$4:$R$97,$CN11)+SUMIFS($AC$4:$AC$97,$AF$4:$AF$97,$BD11,$Q$4:$Q$97,$CN11))} -> 5 | CQ11: {=IF($CN11="-","-",CO11-CP11)} -> -4 | CR11: 1 | CS11: P.1 (4) | CT11: {=IF($CS11="-","-",SUMIFS($AC$4:$AC$97,$AA$4:$AA$97,$BD11,$U$4:$U$97,$CS11)+SUMIFS($AD$4:$AD$97,$AF$4:$AF$97,$BD11,$T$4:$T$97,$CS11))} -> 1 | CU11: 1 | CV11: P.1 (4) | CW11: {=IF(CV11="-","-",BL11)} -> -4 | CX11: 1 | CY11: P.1 (4) | CZ11: {=IF(CY11="-","-",BJ11)} -> 1 | DA11: 1 | DB11: P.1 (4) | DC11: 2 | DD11: 2 | DF11: {=IF(OR(INDEX($AW$6:$AW$97,MATCH($BD11,$AV$6:$AV$97,0))="",DB11="-"),DD11,INDEX($AW$6:$AW$97,MATCH($BD11,$AV$6:$AV$97,0))+DD11/1000)} -> 2 | DG11: 1 | DH11: 2 | DJ11: {=INDEX($DA$6:$DA$53,MATCH($DQ11,$BD$6:$BD$53,0))} -> 1 | DK11: {=SUMIF($BC$6:$BC$53,BC11,$BF$6:$BF$53)} -> 12 | DL11: {=IF(OR(DK11=12,$AJ$99=144),COUNTIFS($DJ$6:$DJ$53,DJ11,$BC$6:$BC$53,BC11),1)} -> 4 | DM11: {=DJ11&"."&DL11} -> 1.4 | DN11: 1 | DP11: 2B | DQ11: {=INDEX($BD$6:$BD$53,MATCH(DP11,$BM$6:$BM$53,0))} -> Bosnia y Herzegovina
A12: NombreEquipo | B12: B | C12: 4 | D12: {=IF(OR(AC12="",AD12=""),"Pendiente",IF(AC12>AD12,"Local",IF(AC12<AD12,"Visitante","Empate")))} -> Local | E12: {=IF(D12="Pendiente","-",INDEX($BT$6:$BT$53,MATCH($AA12,$BD$6:$BD$53,0)))} -> P.1 (4) | F12: {=IF(D12="Pendiente","-",INDEX($BT$6:$BT$53,MATCH($AF12,$BD$6:$BD$53,0)))} -> P.1 (4) | H12: {=IF(D12="Pendiente","-",INDEX($BZ$6:$BZ$53,MATCH($AA12,$BD$6:$BD$53,0)))} -> P.1 (4) | I12: {=IF(D12="Pendiente","-",INDEX($BZ$6:$BZ$53,MATCH($AF12,$BD$6:$BD$53,0)))} -> P.1 (4) | K12: {=IF(D12="Pendiente","-",INDEX($CE$6:$CE$53,MATCH($AA12,$BD$6:$BD$53,0)))} -> P.1 (4) | L12: {=IF(D12="Pendiente","-",INDEX($CE$6:$CE$53,MATCH($AF12,$BD$6:$BD$53,0)))} -> P.1 (4) | N12: {=IF(D12="Pendiente","-",INDEX($CH$6:$CH$53,MATCH($AA12,$BD$6:$BD$53,0)))} -> P.1 (4) | O12: {=IF(D12="Pendiente","-",INDEX($CH$6:$CH$53,MATCH($AF12,$BD$6:$BD$53,0)))} -> P.1 (4) | Q12: {=IF(D12="Pendiente","-",INDEX($CN$6:$CN$53,MATCH($AA12,$BD$6:$BD$53,0)))} -> P.1 (4) | R12: {=IF(D12="Pendiente","-",INDEX($CN$6:$CN$53,MATCH($AF12,$BD$6:$BD$53,0)))} -> P.1 (4) | T12: {=IF(D12="Pendiente","-",INDEX($CS$6:$CS$53,MATCH($AA12,$BD$6:$BD$53,0)))} -> P.1 (4) | U12: {=IF(D12="Pendiente","-",INDEX($CS$6:$CS$53,MATCH($AF12,$BD$6:$BD$53,0)))} -> P.1 (4) | W12: B | X12: 46185.625 | Y12: 46185.625 | Z12: {=$Z$4} -> J1 | AA12: {=A13} -> Canadá | AC12: 1 | AD12: 0 | AF12: {=A14} -> Bosnia y Herzegovina | AG12: {=IF(NOT(OR(ISBLANK(AC12),ISBLANK(AD12))),1,0)} -> 1 | AH12: 3 | AJ12: {=CONCATENATE(AJ3," ",B12)} -> Grupo B | AV12: {=IF(AU13>0,$AV$3,"")} -> ¡EMPATE! Puedes seleccionar el orden de los empatados. | BC12: B | BD12: Catar | BE12: {=BG12*3+BH12+IF($AZ$3="No",0,INDEX($AZ$6:$AZ$97,MATCH(BD12,$AY$6:$AY$97,0)))} -> 4 | BF12: {=BG12+BH12+BI12} -> 3 | BG12: {=COUNTIFS($AA$4:$AA$97,BD12,$D$4:$D$97,"Local")+COUNTIFS($AF$4:$AF$97,BD12,$D$4:$D$97,"Visitante")} -> 1 | BH12: {=COUNTIFS($AA$4:$AA$97,BD12,$D$4:$D$97,"Empate")+COUNTIFS($AF$4:$AF$97,BD12,$D$4:$D$97,"Empate")} -> 1 | BI12: {=COUNTIFS($AF$4:$AF$97,BD12,$D$4:$D$97,"Local")+COUNTIFS($AA$4:$AA$97,BD12,$D$4:$D$97,"Visitante")} -> 1 | BJ12: {=SUMIFS($AC$4:$AC$97,$AA$4:$AA$97,BD12,$D$4:$D$97,"<>"&"Pendiente",$AC$4:$AC$97,"<>"&"",$AD$4:$AD$97,"<>"&"")+SUMIFS($AD$4:$AD$97,$AF$4:$AF$97,BD12,$D$4:$D$97,"<>"&"Pendiente",$AC$4:$AC$97,"<>"&"",$AD$4:$AD$97,"<>"&"")} -> 3 | BK12: {=SUMIFS($AC$4:$AC$97,$AF$4:$AF$97,BD12,$D$4:$D$97,"<>"&"Pendiente",$AC$4:$AC$97,"<>"&"",$AD$4:$AD$97,"<>"&"")+SUMIFS($AD$4:$AD$97,$AA$4:$AA$97,BD12,$D$4:$D$97,"<>"&"Pendiente",$AC$4:$AC$97,"<>"&"",$AD$4:$AD$97,"<>"&"")} -> 3 | BL12: {=BJ12-BK12} -> 0 | BM12: {=DD12&BC12} -> 3B | BN12: {=DH12&BC12} -> 3B | BO12: {=IF(AND($AJ$99=144,BF12>=1),1,0)} -> 0 | BP12: 1 | BQ12: P.1 (4) | BR12: {=IF($BQ12="-","-",BE12)} -> 4 | BS12: 1 | BT12: P.1 (4) | BU12: {=IF($BT12="-","-",COUNTIFS($AA$4:$AA$97,$BD12,$D$4:$D$97,"Local",$F$4:$F$97,$BT12)+COUNTIFS($AF$4:$AF$97,$BD12,$D$4:$D$97,"Visitante",$E$4:$E$97,$BT12))} -> 1 | BV12: {=IF($BT12="-","-",COUNTIFS($AA$4:$AA$97,$BD12,$D$4:$D$97,"Empate",$F$4:$F$97,$BT12)+COUNTIFS($AF$4:$AF$97,$BD12,$D$4:$D$97,"Empate",$E$4:$E$97,$BT12))} -> 1 | BW12: {=IF($BT12="-","-",COUNTIFS($AA$4:$AA$97,$BD12,$D$4:$D$97,"Visitante",$F$4:$F$97,$BT12)+COUNTIFS($AF$4:$AF$97,$BD12,$D$4:$D$97,"Local",$E$4:$E$97,$BT12))} -> 1 | BX12: {=IF($BT12="-","-",BU12*3+BV12)} -> 4 | BY12: 1 | BZ12: P.1 (4) | CA12: {=IF($BZ12="-","-",SUMIFS($AC$4:$AC$97,$AA$4:$AA$97,$BD12,$I$4:$I$97,$BZ12)+SUMIFS($AD$4:$AD$97,$AF$4:$AF$97,$BD12,$H$4:$H$97,$BZ12))} -> 3 | CB12: {=IF($BZ12="-","-",SUMIFS($AD$4:$AD$97,$AA$4:$AA$97,$BD12,$I$4:$I$97,$BZ12)+SUMIFS($AC$4:$AC$97,$AF$4:$AF$97,$BD12,$H$4:$H$97,$BZ12))} -> 3 | CC12: {=IF($BZ12="-","-",CA12-CB12)} -> 0 | CD12: 1 | CE12: P.1 (4) | CF12: {=IF($CE12="-","-",SUMIFS($AC$4:$AC$97,$AA$4:$AA$97,$BD12,$L$4:$L$97,$CE12)+SUMIFS($AD$4:$AD$97,$AF$4:$AF$97,$BD12,$K$4:$K$97,$CE12))} -> 3 | CG12: 1 | CH12: P.1 (4) | CI12: {=IF($CH12="-","-",COUNTIFS($AA$4:$AA$97,$BD12,$D$4:$D$97,"Local",$O$4:$O$97,$CH12)+COUNTIFS($AF$4:$AF$97,$BD12,$D$4:$D$97,"Visitante",$N$4:$N$97,$CH12))} -> 1 | CJ12: {=IF($CH12="-","-",COUNTIFS($AA$4:$AA$97,$BD12,$D$4:$D$97,"Empate",$O$4:$O$97,$CH12)+COUNTIFS($AF$4:$AF$97,$BD12,$D$4:$D$97,"Empate",$N$4:$N$97,$CH12))} -> 1 | CK12: {=IF($CH12="-","-",COUNTIFS($AA$4:$AA$97,$BD12,$D$4:$D$97,"Visitante",$O$4:$O$97,$CH12)+COUNTIFS($AF$4:$AF$97,$BD12,$D$4:$D$97,"Local",$N$4:$N$97,$CH12))} -> 1 | CL12: {=IF($CH12="-","-",CI12*3+CJ12)} -> 4 | CM12: 1 | CN12: P.1 (4) | CO12: {=IF($CN12="-","-",SUMIFS($AC$4:$AC$97,$AA$4:$AA$97,$BD12,$R$4:$R$97,$CN12)+SUMIFS($AD$4:$AD$97,$AF$4:$AF$97,$BD12,$Q$4:$Q$97,$CN12))} -> 3 | CP12: {=IF($CN12="-","-",SUMIFS($AD$4:$AD$97,$AA$4:$AA$97,$BD12,$R$4:$R$97,$CN12)+SUMIFS($AC$4:$AC$97,$AF$4:$AF$97,$BD12,$Q$4:$Q$97,$CN12))} -> 3 | CQ12: {=IF($CN12="-","-",CO12-CP12)} -> 0 | CR12: 1 | CS12: P.1 (4) | CT12: {=IF($CS12="-","-",SUMIFS($AC$4:$AC$97,$AA$4:$AA$97,$BD12,$U$4:$U$97,$CS12)+SUMIFS($AD$4:$AD$97,$AF$4:$AF$97,$BD12,$T$4:$T$97,$CS12))} -> 3 | CU12: 1 | CV12: P.1 (4) | CW12: {=IF(CV12="-","-",BL12)} -> 0 | CX12: 1 | CY12: P.1 (4) | CZ12: {=IF(CY12="-","-",BJ12)} -> 3 | DA12: 1 | DB12: P.1 (4) | DC12: 3 | DD12: 3 | DF12: {=IF(OR(INDEX($AW$6:$AW$97,MATCH($BD12,$AV$6:$AV$97,0))="",DB12="-"),DD12,INDEX($AW$6:$AW$97,MATCH($BD12,$AV$6:$AV$97,0))+DD12/1000)} -> 3 | DG12: 2 | DH12: 3 | DJ12: {=INDEX($DA$6:$DA$53,MATCH($DQ12,$BD$6:$BD$53,0))} -> 1 | DK12: {=SUMIF($BC$6:$BC$53,BC12,$BF$6:$BF$53)} -> 12 | DL12: {=IF(OR(DK12=12,$AJ$99=144),COUNTIFS($DJ$6:$DJ$53,DJ12,$BC$6:$BC$53,BC12),1)} -> 4 | DM12: {=DJ12&"."&DL12} -> 1.4 | DN12: 1 | DP12: 3B | DQ12: {=INDEX($BD$6:$BD$53,MATCH(DP12,$BM$6:$BM$53,0))} -> Catar
A13: Canadá | D13: {=IF(OR(AC13="",AD13=""),"Pendiente",IF(AC13>AD13,"Local",IF(AC13<AD13,"Visitante","Empate")))} -> Empate | E13: {=IF(D13="Pendiente","-",INDEX($BT$6:$BT$53,MATCH($AA13,$BD$6:$BD$53,0)))} -> P.1 (4) | F13: {=IF(D13="Pendiente","-",INDEX($BT$6:$BT$53,MATCH($AF13,$BD$6:$BD$53,0)))} -> P.1 (4) | H13: {=IF(D13="Pendiente","-",INDEX($BZ$6:$BZ$53,MATCH($AA13,$BD$6:$BD$53,0)))} -> P.1 (4) | I13: {=IF(D13="Pendiente","-",INDEX($BZ$6:$BZ$53,MATCH($AF13,$BD$6:$BD$53,0)))} -> P.1 (4) | K13: {=IF(D13="Pendiente","-",INDEX($CE$6:$CE$53,MATCH($AA13,$BD$6:$BD$53,0)))} -> P.1 (4) | L13: {=IF(D13="Pendiente","-",INDEX($CE$6:$CE$53,MATCH($AF13,$BD$6:$BD$53,0)))} -> P.1 (4) | N13: {=IF(D13="Pendiente","-",INDEX($CH$6:$CH$53,MATCH($AA13,$BD$6:$BD$53,0)))} -> P.1 (4) | O13: {=IF(D13="Pendiente","-",INDEX($CH$6:$CH$53,MATCH($AF13,$BD$6:$BD$53,0)))} -> P.1 (4) | Q13: {=IF(D13="Pendiente","-",INDEX($CN$6:$CN$53,MATCH($AA13,$BD$6:$BD$53,0)))} -> P.1 (4) | R13: {=IF(D13="Pendiente","-",INDEX($CN$6:$CN$53,MATCH($AF13,$BD$6:$BD$53,0)))} -> P.1 (4) | T13: {=IF(D13="Pendiente","-",INDEX($CS$6:$CS$53,MATCH($AA13,$BD$6:$BD$53,0)))} -> P.1 (4) | U13: {=IF(D13="Pendiente","-",INDEX($CS$6:$CS$53,MATCH($AF13,$BD$6:$BD$53,0)))} -> P.1 (4) | X13: 46186.625 | Y13: 46186.625 | Z13: {=$Z$4} -> J1 | AA13: {=A15} -> Catar | AC13: 1 | AD13: 1 | AF13: {=A16} -> Suiza | AG13: {=IF(NOT(OR(ISBLANK(AC13),ISBLANK(AD13))),1,0)} -> 1 | AH13: 8 | AJ13: {=AJ5} -> Pos | AL13: {=AL5} -> Selección | AM13: {=AM5} -> Pts | AN13: {=AN5} -> J | AO13: {=AO5} -> G | AP13: {=AP5} -> E | AQ13: {=AQ5} -> P | AR13: {=AR5} -> GF | AS13: {=AS5} -> GC | AT13: {=AT5} -> DG | AU13: {=COUNTIF(AU14:AU17,">1")} -> 4 | AY13: {=AL13} -> Selección | AZ13: Puntos penalizados | BC13: B | BD13: Suiza | BE13: {=BG13*3+BH13+IF($AZ$3="No",0,INDEX($AZ$6:$AZ$97,MATCH(BD13,$AY$6:$AY$97,0)))} -> 5 | BF13: {=BG13+BH13+BI13} -> 3 | BG13: {=COUNTIFS($AA$4:$AA$97,BD13,$D$4:$D$97,"Local")+COUNTIFS($AF$4:$AF$97,BD13,$D$4:$D$97,"Visitante")} -> 1 | BH13: {=COUNTIFS($AA$4:$AA$97,BD13,$D$4:$D$97,"Empate")+COUNTIFS($AF$4:$AF$97,BD13,$D$4:$D$97,"Empate")} -> 2 | BI13: {=COUNTIFS($AF$4:$AF$97,BD13,$D$4:$D$97,"Local")+COUNTIFS($AA$4:$AA$97,BD13,$D$4:$D$97,"Visitante")} -> 0 | BJ13: {=SUMIFS($AC$4:$AC$97,$AA$4:$AA$97,BD13,$D$4:$D$97,"<>"&"Pendiente",$AC$4:$AC$97,"<>"&"",$AD$4:$AD$97,"<>"&"")+SUMIFS($AD$4:$AD$97,$AF$4:$AF$97,BD13,$D$4:$D$97,"<>"&"Pendiente",$AC$4:$AC$97,"<>"&"",$AD$4:$AD$97,"<>"&"")} -> 5 | BK13: {=SUMIFS($AC$4:$AC$97,$AF$4:$AF$97,BD13,$D$4:$D$97,"<>"&"Pendiente",$AC$4:$AC$97,"<>"&"",$AD$4:$AD$97,"<>"&"")+SUMIFS($AD$4:$AD$97,$AA$4:$AA$97,BD13,$D$4:$D$97,"<>"&"Pendiente",$AC$4:$AC$97,"<>"&"",$AD$4:$AD$97,"<>"&"")} -> 3 | BL13: {=BJ13-BK13} -> 2 | BM13: {=DD13&BC13} -> 4B | BN13: {=DH13&BC13} -> 4B | BO13: {=IF(AND($AJ$99=144,BF13>=1),1,0)} -> 0 | BP13: 1 | BQ13: P.1 (4) | BR13: {=IF($BQ13="-","-",BE13)} -> 5 | BS13: 1 | BT13: P.1 (4) | BU13: {=IF($BT13="-","-",COUNTIFS($AA$4:$AA$97,$BD13,$D$4:$D$97,"Local",$F$4:$F$97,$BT13)+COUNTIFS($AF$4:$AF$97,$BD13,$D$4:$D$97,"Visitante",$E$4:$E$97,$BT13))} -> 1 | BV13: {=IF($BT13="-","-",COUNTIFS($AA$4:$AA$97,$BD13,$D$4:$D$97,"Empate",$F$4:$F$97,$BT13)+COUNTIFS($AF$4:$AF$97,$BD13,$D$4:$D$97,"Empate",$E$4:$E$97,$BT13))} -> 2 | BW13: {=IF($BT13="-","-",COUNTIFS($AA$4:$AA$97,$BD13,$D$4:$D$97,"Visitante",$F$4:$F$97,$BT13)+COUNTIFS($AF$4:$AF$97,$BD13,$D$4:$D$97,"Local",$E$4:$E$97,$BT13))} -> 0 | BX13: {=IF($BT13="-","-",BU13*3+BV13)} -> 5 | BY13: 1 | BZ13: P.1 (4) | CA13: {=IF($BZ13="-","-",SUMIFS($AC$4:$AC$97,$AA$4:$AA$97,$BD13,$I$4:$I$97,$BZ13)+SUMIFS($AD$4:$AD$97,$AF$4:$AF$97,$BD13,$H$4:$H$97,$BZ13))} -> 5 | CB13: {=IF($BZ13="-","-",SUMIFS($AD$4:$AD$97,$AA$4:$AA$97,$BD13,$I$4:$I$97,$BZ13)+SUMIFS($AC$4:$AC$97,$AF$4:$AF$97,$BD13,$H$4:$H$97,$BZ13))} -> 3 | CC13: {=IF($BZ13="-","-",CA13-CB13)} -> 2 | CD13: 1 | CE13: P.1 (4) | CF13: {=IF($CE13="-","-",SUMIFS($AC$4:$AC$97,$AA$4:$AA$97,$BD13,$L$4:$L$97,$CE13)+SUMIFS($AD$4:$AD$97,$AF$4:$AF$97,$BD13,$K$4:$K$97,$CE13))} -> 5 | CG13: 1 | CH13: P.1 (4) | CI13: {=IF($CH13="-","-",COUNTIFS($AA$4:$AA$97,$BD13,$D$4:$D$97,"Local",$O$4:$O$97,$CH13)+COUNTIFS($AF$4:$AF$97,$BD13,$D$4:$D$97,"Visitante",$N$4:$N$97,$CH13))} -> 1 | CJ13: {=IF($CH13="-","-",COUNTIFS($AA$4:$AA$97,$BD13,$D$4:$D$97,"Empate",$O$4:$O$97,$CH13)+COUNTIFS($AF$4:$AF$97,$BD13,$D$4:$D$97,"Empate",$N$4:$N$97,$CH13))} -> 2 | CK13: {=IF($CH13="-","-",COUNTIFS($AA$4:$AA$97,$BD13,$D$4:$D$97,"Visitante",$O$4:$O$97,$CH13)+COUNTIFS($AF$4:$AF$97,$BD13,$D$4:$D$97,"Local",$N$4:$N$97,$CH13))} -> 0 | CL13: {=IF($CH13="-","-",CI13*3+CJ13)} -> 5 | CM13: 1 | CN13: P.1 (4) | CO13: {=IF($CN13="-","-",SUMIFS($AC$4:$AC$97,$AA$4:$AA$97,$BD13,$R$4:$R$97,$CN13)+SUMIFS($AD$4:$AD$97,$AF$4:$AF$97,$BD13,$Q$4:$Q$97,$CN13))} -> 5 | CP13: {=IF($CN13="-","-",SUMIFS($AD$4:$AD$97,$AA$4:$AA$97,$BD13,$R$4:$R$97,$CN13)+SUMIFS($AC$4:$AC$97,$AF$4:$AF$97,$BD13,$Q$4:$Q$97,$CN13))} -> 3 | CQ13: {=IF($CN13="-","-",CO13-CP13)} -> 2 | CR13: 1 | CS13: P.1 (4) | CT13: {=IF($CS13="-","-",SUMIFS($AC$4:$AC$97,$AA$4:$AA$97,$BD13,$U$4:$U$97,$CS13)+SUMIFS($AD$4:$AD$97,$AF$4:$AF$97,$BD13,$T$4:$T$97,$CS13))} -> 5 | CU13: 1 | CV13: P.1 (4) | CW13: {=IF(CV13="-","-",BL13)} -> 2 | CX13: 1 | CY13: P.1 (4) | CZ13: {=IF(CY13="-","-",BJ13)} -> 5 | DA13: 1 | DB13: P.1 (4) | DC13: 4 | DD13: 4 | DF13: {=IF(OR(INDEX($AW$6:$AW$97,MATCH($BD13,$AV$6:$AV$97,0))="",DB13="-"),DD13,INDEX($AW$6:$AW$97,MATCH($BD13,$AV$6:$AV$97,0))+DD13/1000)} -> 4 | DG13: 3 | DH13: 4 | DJ13: {=INDEX($DA$6:$DA$53,MATCH($DQ13,$BD$6:$BD$53,0))} -> 1 | DK13: {=SUMIF($BC$6:$BC$53,BC13,$BF$6:$BF$53)} -> 12 | DL13: {=IF(OR(DK13=12,$AJ$99=144),COUNTIFS($DJ$6:$DJ$53,DJ13,$BC$6:$BC$53,BC13),1)} -> 4 | DM13: {=DJ13&"."&DL13} -> 1.4 | DN13: 1 | DP13: 4B | DQ13: {=INDEX($BD$6:$BD$53,MATCH(DP13,$BM$6:$BM$53,0))} -> Suiza
A14: Bosnia y Herzegovina | D14: {=IF(OR(AC14="",AD14=""),"Pendiente",IF(AC14>AD14,"Local",IF(AC14<AD14,"Visitante","Empate")))} -> Local | E14: {=IF(D14="Pendiente","-",INDEX($BT$6:$BT$53,MATCH($AA14,$BD$6:$BD$53,0)))} -> P.1 (4) | F14: {=IF(D14="Pendiente","-",INDEX($BT$6:$BT$53,MATCH($AF14,$BD$6:$BD$53,0)))} -> P.1 (4) | H14: {=IF(D14="Pendiente","-",INDEX($BZ$6:$BZ$53,MATCH($AA14,$BD$6:$BD$53,0)))} -> P.1 (4) | I14: {=IF(D14="Pendiente","-",INDEX($BZ$6:$BZ$53,MATCH($AF14,$BD$6:$BD$53,0)))} -> P.1 (4) | K14: {=IF(D14="Pendiente","-",INDEX($CE$6:$CE$53,MATCH($AA14,$BD$6:$BD$53,0)))} -> P.1 (4) | L14: {=IF(D14="Pendiente","-",INDEX($CE$6:$CE$53,MATCH($AF14,$BD$6:$BD$53,0)))} -> P.1 (4) | N14: {=IF(D14="Pendiente","-",INDEX($CH$6:$CH$53,MATCH($AA14,$BD$6:$BD$53,0)))} -> P.1 (4) | O14: {=IF(D14="Pendiente","-",INDEX($CH$6:$CH$53,MATCH($AF14,$BD$6:$BD$53,0)))} -> P.1 (4) | Q14: {=IF(D14="Pendiente","-",INDEX($CN$6:$CN$53,MATCH($AA14,$BD$6:$BD$53,0)))} -> P.1 (4) | R14: {=IF(D14="Pendiente","-",INDEX($CN$6:$CN$53,MATCH($AF14,$BD$6:$BD$53,0)))} -> P.1 (4) | T14: {=IF(D14="Pendiente","-",INDEX($CS$6:$CS$53,MATCH($AA14,$BD$6:$BD$53,0)))} -> P.1 (4) | U14: {=IF(D14="Pendiente","-",INDEX($CS$6:$CS$53,MATCH($AF14,$BD$6:$BD$53,0)))} -> P.1 (4) | X14: 46191.625 | Y14: 46191.625 | Z14: {=$Z$6} -> J2 | AA14: {=A16} -> Suiza | AC14: 3 | AD14: 1 | AF14: {=A14} -> Bosnia y Herzegovina | AG14: {=IF(NOT(OR(ISBLANK(AC14),ISBLANK(AD14))),1,0)} -> 1 | AH14: 26 | AI14: {=AJ14&$B$12} -> 1B | AJ14: 1 | AL14: {=IFERROR(INDEX($BD$6:$BD$53,MATCH(AI14,$BN$6:$BN$53,0)),"")} -> Canadá | AM14: {=INDEX($BE$6:$BN$53,MATCH($AL14,$BD$6:$BD$53,0),MATCH(AM$5,$BE$5:$BN$5,0))} -> 7 | AN14: {=INDEX($BE$6:$BN$53,MATCH($AL14,$BD$6:$BD$53,0),MATCH(AN$5,$BE$5:$BN$5,0))} -> 3 | AO14: {=INDEX($BE$6:$BN$53,MATCH($AL14,$BD$6:$BD$53,0),MATCH(AO$5,$BE$5:$BN$5,0))} -> 2 | AP14: {=INDEX($BE$6:$BN$53,MATCH($AL14,$BD$6:$BD$53,0),MATCH(AP$5,$BE$5:$BN$5,0))} -> 1 | AQ14: {=INDEX($BE$6:$BN$53,MATCH($AL14,$BD$6:$BD$53,0),MATCH(AQ$5,$BE$5:$BN$5,0))} -> 0 | AR14: {=INDEX($BE$6:$BN$53,MATCH($AL14,$BD$6:$BD$53,0),MATCH(AR$5,$BE$5:$BN$5,0))} -> 4 | AS14: {=INDEX($BE$6:$BN$53,MATCH($AL14,$BD$6:$BD$53,0),MATCH(AS$5,$BE$5:$BN$5,0))} -> 2 | AT14: {=INDEX($BE$6:$BN$53,MATCH($AL14,$BD$6:$BD$53,0),MATCH(AT$5,$BE$5:$BN$5,0))} -> 2 | AU14: {=INDEX($DL$6:$DL$53,MATCH(AI14,$DP$6:$DP$53,0))} -> 4 | AV14: {=INDEX($BD$6:$BD$53,MATCH(AI14,$BM$6:$BM$53,0))} -> Canadá | AY14: {=A13} -> Canadá | BC14: C | BD14: Brasil | BE14: {=BG14*3+BH14+IF($AZ$3="No",0,INDEX($AZ$6:$AZ$97,MATCH(BD14,$AY$6:$AY$97,0)))} -> 9 | BF14: {=BG14+BH14+BI14} -> 3 | BG14: {=COUNTIFS($AA$4:$AA$97,BD14,$D$4:$D$97,"Local")+COUNTIFS($AF$4:$AF$97,BD14,$D$4:$D$97,"Visitante")} -> 3 | BH14: {=COUNTIFS($AA$4:$AA$97,BD14,$D$4:$D$97,"Empate")+COUNTIFS($AF$4:$AF$97,BD14,$D$4:$D$97,"Empate")} -> 0 | BI14: {=COUNTIFS($AF$4:$AF$97,BD14,$D$4:$D$97,"Local")+COUNTIFS($AA$4:$AA$97,BD14,$D$4:$D$97,"Visitante")} -> 0 | BJ14: {=SUMIFS($AC$4:$AC$97,$AA$4:$AA$97,BD14,$D$4:$D$97,"<>"&"Pendiente",$AC$4:$AC$97,"<>"&"",$AD$4:$AD$97,"<>"&"")+SUMIFS($AD$4:$AD$97,$AF$4:$AF$97,BD14,$D$4:$D$97,"<>"&"Pendiente",$AC$4:$AC$97,"<>"&"",$AD$4:$AD$97,"<>"&"")} -> 10 | BK14: {=SUMIFS($AC$4:$AC$97,$AF$4:$AF$97,BD14,$D$4:$D$97,"<>"&"Pendiente",$AC$4:$AC$97,"<>"&"",$AD$4:$AD$97,"<>"&"")+SUMIFS($AD$4:$AD$97,$AA$4:$AA$97,BD14,$D$4:$D$97,"<>"&"Pendiente",$AC$4:$AC$97,"<>"&"",$AD$4:$AD$97,"<>"&"")} -> 2 | BL14: {=BJ14-BK14} -> 8 | BM14: {=DD14&BC14} -> 1C | BN14: {=DH14&BC14} -> 1C | BO14: {=IF(AND($AJ$99=144,BF14>=1),1,0)} -> 0 | BP14: 1 | BQ14: P.1 (4) | BR14: {=IF($BQ14="-","-",BE14)} -> 9 | BS14: 1 | BT14: P.1 (4) | BU14: {=IF($BT14="-","-",COUNTIFS($AA$4:$AA$97,$BD14,$D$4:$D$97,"Local",$F$4:$F$97,$BT14)+COUNTIFS($AF$4:$AF$97,$BD14,$D$4:$D$97,"Visitante",$E$4:$E$97,$BT14))} -> 3 | BV14: {=IF($BT14="-","-",COUNTIFS($AA$4:$AA$97,$BD14,$D$4:$D$97,"Empate",$F$4:$F$97,$BT14)+COUNTIFS($AF$4:$AF$97,$BD14,$D$4:$D$97,"Empate",$E$4:$E$97,$BT14))} -> 0 | BW14: {=IF($BT14="-","-",COUNTIFS($AA$4:$AA$97,$BD14,$D$4:$D$97,"Visitante",$F$4:$F$97,$BT14)+COUNTIFS($AF$4:$AF$97,$BD14,$D$4:$D$97,"Local",$E$4:$E$97,$BT14))} -> 0 | BX14: {=IF($BT14="-","-",BU14*3+BV14)} -> 9 | BY14: 1 | BZ14: P.1 (4) | CA14: {=IF($BZ14="-","-",SUMIFS($AC$4:$AC$97,$AA$4:$AA$97,$BD14,$I$4:$I$97,$BZ14)+SUMIFS($AD$4:$AD$97,$AF$4:$AF$97,$BD14,$H$4:$H$97,$BZ14))} -> 10 | CB14: {=IF($BZ14="-","-",SUMIFS($AD$4:$AD$97,$AA$4:$AA$97,$BD14,$I$4:$I$97,$BZ14)+SUMIFS($AC$4:$AC$97,$AF$4:$AF$97,$BD14,$H$4:$H$97,$BZ14))} -> 2 | CC14: {=IF($BZ14="-","-",CA14-CB14)} -> 8 | CD14: 1 | CE14: P.1 (4) | CF14: {=IF($CE14="-","-",SUMIFS($AC$4:$AC$97,$AA$4:$AA$97,$BD14,$L$4:$L$97,$CE14)+SUMIFS($AD$4:$AD$97,$AF$4:$AF$97,$BD14,$K$4:$K$97,$CE14))} -> 10 | CG14: 1 | CH14: P.1 (4) | CI14: {=IF($CH14="-","-",COUNTIFS($AA$4:$AA$97,$BD14,$D$4:$D$97,"Local",$O$4:$O$97,$CH14)+COUNTIFS($AF$4:$AF$97,$BD14,$D$4:$D$97,"Visitante",$N$4:$N$97,$CH14))} -> 3 | CJ14: {=IF($CH14="-","-",COUNTIFS($AA$4:$AA$97,$BD14,$D$4:$D$97,"Empate",$O$4:$O$97,$CH14)+COUNTIFS($AF$4:$AF$97,$BD14,$D$4:$D$97,"Empate",$N$4:$N$97,$CH14))} -> 0 | CK14: {=IF($CH14="-","-",COUNTIFS($AA$4:$AA$97,$BD14,$D$4:$D$97,"Visitante",$O$4:$O$97,$CH14)+COUNTIFS($AF$4:$AF$97,$BD14,$D$4:$D$97,"Local",$N$4:$N$97,$CH14))} -> 0 | CL14: {=IF($CH14="-","-",CI14*3+CJ14)} -> 9 | CM14: 1 | CN14: P.1 (4) | CO14: {=IF($CN14="-","-",SUMIFS($AC$4:$AC$97,$AA$4:$AA$97,$BD14,$R$4:$R$97,$CN14)+SUMIFS($AD$4:$AD$97,$AF$4:$AF$97,$BD14,$Q$4:$Q$97,$CN14))} -> 10 | CP14: {=IF($CN14="-","-",SUMIFS($AD$4:$AD$97,$AA$4:$AA$97,$BD14,$R$4:$R$97,$CN14)+SUMIFS($AC$4:$AC$97,$AF$4:$AF$97,$BD14,$Q$4:$Q$97,$CN14))} -> 2 | CQ14: {=IF($CN14="-","-",CO14-CP14)} -> 8 | CR14: 1 | CS14: P.1 (4) | CT14: {=IF($CS14="-","-",SUMIFS($AC$4:$AC$97,$AA$4:$AA$97,$BD14,$U$4:$U$97,$CS14)+SUMIFS($AD$4:$AD$97,$AF$4:$AF$97,$BD14,$T$4:$T$97,$CS14))} -> 10 | CU14: 1 | CV14: P.1 (4) | CW14: {=IF(CV14="-","-",BL14)} -> 8 | CX14: 1 | CY14: P.1 (4) | CZ14: {=IF(CY14="-","-",BJ14)} -> 10 | DA14: 1 | DB14: P.1 (4) | DC14: 1 | DD14: 1 | DF14: {=IF(OR(INDEX($AW$6:$AW$97,MATCH($BD14,$AV$6:$AV$97,0))="",DB14="-"),DD14,INDEX($AW$6:$AW$97,MATCH($BD14,$AV$6:$AV$97,0))+DD14/1000)} -> 1 | DG14: 0 | DH14: 1 | DJ14: {=INDEX($DA$6:$DA$53,MATCH($DQ14,$BD$6:$BD$53,0))} -> 1 | DK14: {=SUMIF($BC$6:$BC$53,BC14,$BF$6:$BF$53)} -> 12 | DL14: {=IF(OR(DK14=12,$AJ$99=144),COUNTIFS($DJ$6:$DJ$53,DJ14,$BC$6:$BC$53,BC14),1)} -> 4 | DM14: {=DJ14&"."&DL14} -> 1.4 | DN14: 1 | DP14: 1C | DQ14: {=INDEX($BD$6:$BD$53,MATCH(DP14,$BM$6:$BM$53,0))} -> Brasil
